Workbook
Name \a: #REF!
Name \a: #REF!
Name \a: #REF!
Name \a: #REF!
Name \a: #REF!
Name \a: #REF!
Name \a: #REF!
Name \a: #REF!
Name \a: #REF!
Name \z: #REF!
Name \z: #REF!
Name \z: #REF!
Name \z: #REF!
Name \z: #REF!
Name \z: #REF!
Name \z: #REF!
Name \z: #REF!
Name \z: #REF!
Name _4_93: '[1]NCR-03'!#REF!
Name _4_93: '[1]NCR-03'!#REF!
Name _4_93: '[1]NCR-03'!#REF!
Name _4_93: '[1]NCR-03'!#REF!
Name _4_93: '[1]NCR-03'!#REF!
Name _4_93: '[1]NCR-03'!#REF!
Name _4_93: '[1]NCR-03'!#REF!
Name _4_93: '[1]NCR-03'!#REF!
Name _4_93: '[1]NCR-03'!#REF!
Name _84AOMM: #N/A
Name _93: #REF!
Name _93: #REF!
Name _93: #REF!
Name _93: #REF!
Name _93: #REF!
Name _93: #REF!
Name _93: #REF!
Name _93: #REF!
Name _93: #REF!
Name _R1: #REF!
Name _R1: #REF!
Name _R10: #REF!
Name _R10: #REF!
Name _R11: #REF!
Name _R11: #REF!
Name _R12: #REF!
Name _R2: #REF!
Name _R3: #REF!
Name _R4: #REF!
Name _R5: #REF!
Name _R6: #REF!
Name _R7: #REF!
Name _R8: #REF!
Name _r82001: #REF!
Name _R9: #REF!
Name _REG1: #N/A
Name _REG4: '[1]NCR-03'!#REF!
Name _REG4: '[1]NCR-03'!#REF!
Name A: #N/A
Name AOMM: #REF!
Name AOMM_93: #REF!
Name ARMM: #REF!

Sheet Table_All_SR (From Editing)
F4: Rice, Special | M4: Rice, Well Milled | T4: Rice, Regular Milled | AB4: Fresh Beef, Meat with Bones | AI4: Fresh Beef, Pure Meat | AP4: Fresh Pork, Kasim | AW4: Fresh Pork, Liempo | BD4: Fresh Pork, Meat with Bones | BK4: Dressed Chicken | BR4: Chicken egg, med. (piece) | BZ4: Bangus | CG4: Galunggong | CN4: Tilapia | CV4: Ampalaya | DC4: Cabbage | DJ4: Carrot | DQ4: Eggplant | DX4: Baguio Beans | EE4: Pechay, Native | EL4: String Beans | ES4: Tomato | EZ4: White Potato | FH4: Onion, Red | FO4: Garlic, Native | FV4: Garlic, Imported | GC4: Ginger, Hawaiian | GK4: Banana, Lakatan | GR4: Banana, Latundan | GY4: Calamansi | HF4: Mango, Carabao | HM4: Papaya | HU4: Cooking oil | IB4: Brown Sugar | II4: Refined Sugar
B5: Region / Province | C5: RICE, SPECIAL | J5: RICE, WELL MILLED | Q5: RICE, REGULAR MILLED | Z5: BEEF,WITH BONES | AG5: BEEF, PURE MEAT | AN5: PORK, KASIM | AU5: PORK, LIEMPO | BB5: PORK, WITH BONES | BI5: DRESSED CHICKEN | BP5: CHICKEN EGG, MED. (per piece) | BX5: BANGUS | CE5: GALUNGGONG | CL5: TILAPIA | CT5: AMPALAYA | DA5: CABBAGE | DH5: CARROT | DO5: EGGPLANT | DV5: BAGUIO BEANS | EC5: PECHAY, NATIVE | EJ5: STRING BEANS | EQ5: TOMATO | EX5: WHITE POTATO | FF5: ONION, RED | FM5: GARLIC, NATIVE | FT5: GARLIC, IMPORTED | GA5: GINGER, HAWAIIAN | GI5: BANANA, LAKATAN | GP5: BANANA, LATUNDAN | GW5: CALAMANSI | HD5: MANGO, CARABAO | HK5: PAPAYA | HS5: COOKING OIL (in PhP) | HZ5: BROWN SUGAR (in PhP per Kilogram) | IG5: REFINED SUGAR (in PhP per Kilogram)
C6: Concatenate | D6: 2nd Phase Previous Month | F6: 1st Phase Current Month | H6: 2nd Phase Current Month | J6: Concatenate | K6: 2nd Phase Previous Month | M6: 1st Phase Current Month | O6: 2nd Phase Current Month | Q6: Concatenate | R6: 2nd Phase Previous Month | T6: 1st Phase Current Month | V6: 2nd Phase Current Month | Y6: Concatenate | Z6: 2nd Phase Previous Month | AB6: 1st Phase Current Month | AD6: 2nd Phase Current Month | AF6: Concatenate | AG6: 2nd Phase Previous Month | AI6: 1st Phase Current Month | AK6: 2nd Phase Current Month | AM6: Concatenate | AN6: 2nd Phase Previous Month | AP6: 1st Phase Current Month | AR6: 2nd Phase Current Month | AT6: Concatenate | AU6: 2nd Phase Previous Month | AW6: 1st Phase Current Month | AY6: 2nd Phase Current Month | BA6: Concatenate | BB6: 2nd Phase Previous Month | BD6: 1st Phase Current Month | BF6: 2nd Phase Current Month | BH6: Concatenate | BI6: 2nd Phase Previous Month | BK6: 1st Phase Current Month | BM6: 2nd Phase Current Month | BO6: Concatenate | BP6: 2nd Phase Previous Month | BR6: 1st Phase Current Month | BT6: 2nd Phase Current Month | BW6: Concatenate | BX6: 2nd Phase Previous Month | BZ6: 1st Phase Current Month | CB6: 2nd Phase Current Month | CD6: Concatenate | CE6: 2nd Phase Previous Month | CG6: 1st Phase Current Month | CI6: 2nd Phase Current Month | CK6: Concatenate | CL6: 2nd Phase Previous Month | CN6: 1st Phase Current Month | CP6: 2nd Phase Current Month | CS6: Concatenate | CT6: 2nd Phase Previous Month | CV6: 1st Phase Current Month | CX6: 2nd Phase Current Month | CZ6: Concatenate | DA6: 2nd Phase Previous Month | DC6: 1st Phase Current Month | DE6: 2nd Phase Current Month | DG6: Concatenate | DH6: 2nd Phase Previous Month | DJ6: 1st Phase Current Month | DL6: 2nd Phase Current Month | DN6: Concatenate | DO6: 2nd Phase Previous Month | DQ6: 1st Phase Current Month | DS6: 2nd Phase Current Month | DU6: Concatenate | DV6: 2nd Phase Previous Month | DX6: 1st Phase Current Month | DZ6: 2nd Phase Current Month | EB6: Concatenate | EC6: 2nd Phase Previous Month | EE6: 1st Phase Current Month | EG6: 2nd Phase Current Month | EI6: Concatenate | EJ6: 2nd Phase Previous Month | EL6: 1st Phase Current Month | EN6: 2nd Phase Current Month | EP6: Concatenate | EQ6: 2nd Phase Previous Month | ES6: 1st Phase Current Month | EU6: 2nd Phase Current Month | EW6: Concatenate | EX6: 2nd Phase Previous Month | EZ6: 1st Phase Current Month | FB6: 2nd Phase Current Month | FE6: Concatenate | FF6: 2nd Phase Previous Month | FH6: 1st Phase Current Month | FJ6: 2nd Phase Current Month | FL6: Concatenate | FM6: 2nd Phase Previous Month | FO6: 1st Phase Current Month | FQ6: 2nd Phase Current Month | FS6: Concatenate | FT6: 2nd Phase Previous Month | FV6: 1st Phase Current Month | FX6: 2nd Phase Current Month | FZ6: Concatenate | GA6: 2nd Phase Previous Month | GC6: 1st Phase Current Month | GE6: 2nd Phase Current Month | GH6: Concatenate | GI6: 2nd Phase Previous Month | GK6: 1st Phase Current Month | GM6: 2nd Phase Current Month | GO6: Concatenate | GP6: 2nd Phase Previous Month | GR6: 1st Phase Current Month | GT6: 2nd Phase Current Month | GV6: Concatenate | GW6: 2nd Phase Previous Month | GY6: 1st Phase Current Month | HA6: 2nd Phase Current Month | HC6: Concatenate | HD6: 2nd Phase Previous Month | HF6: 1st Phase Current Month | HH6: 2nd Phase Current Month | HJ6: Concatenate | HK6: 2nd Phase Previous Month | HM6: 1st Phase Current Month | HO6: 2nd Phase Current Month | HR6: Concatenate | HS6: 2nd Phase Previous Month | HU6: 1st Phase Current Month | HW6: 2nd Phase Current Month | HY6: Concatenate | HZ6: 2nd Phase Previous Month | IB6: 1st Phase Current Month | ID6: 2nd Phase Current Month | IF6: Concatenate | IG6: 2nd Phase Previous Month | II6: 1st Phase Current Month | IK6: 2nd Phase Current Month
D7: -1 | F7: -2 | H7: -3 | K7: -4 | M7: -5 | O7: -6 | R7: -7 | T7: -8 | V7: -9 | Z7: -1 | AB7: -2 | AD7: -3 | AG7: -4 | AI7: -5 | AK7: -6 | AN7: -7 | AP7: -8 | AR7: -9 | AU7: -10 | AW7: -11 | AY7: -12 | BB7: -13 | BD7: -14 | BF7: -15 | BI7: -16 | BK7: -17 | BM7: -18 | BP7: -19 | BR7: -20 | BT7: -21 | BX7: -1 | BZ7: -2 | CB7: -3 | CE7: -4 | CG7: -5 | CI7: -6 | CL7: -7 | CN7: -8 | CP7: -9 | CT7: -1 | CV7: -2 | CX7: -3 | DA7: -4 | DC7: -5 | DE7: -6 | DH7: -7 | DJ7: -8 | DL7: -9 | DO7: -10 | DQ7: -11 | DS7: -12 | DV7: -13 | DX7: -14 | DZ7: -15 | EC7: -16 | EE7: -17 | EG7: -18 | EJ7: -19 | EL7: -20 | EN7: -21 | EQ7: -22 | ES7: -23 | EU7: -24 | EX7: -25 | EZ7: -26 | FB7: -27 | FF7: -1 | FH7: -2 | FJ7: -3 | FM7: -4 | FO7: -5 | FQ7: -6 | FT7: -7 | FV7: -8 | FX7: -9 | GA7: -10 | GC7: -11 | GE7: -12 | GI7: -1 | GK7: -2 | GM7: -3 | GP7: -4 | GR7: -5 | GT7: -6 | GW7: -7 | GY7: -8 | HA7: -9 | HD7: -10 | HF7: -11 | HH7: -12 | HK7: -13 | HM7: -14 | HO7: -15 | HS7: -1 | HU7: -2 | HW7: -3 | HZ7: -4 | IB7: -5 | ID7: -6 | IG7: -7 | II7: -8 | IK7: -9
A8: PHILIPPINES | B8: Philippines | C8: PHILIPPINESRice, Special | D8: 56.87 | E8: 0 | F8: 56.62 | G8: r | H8: 56.84 | I8: 0 | J8: PHILIPPINESRice, Well Milled | K8: 47.07 | L8: 0 | M8: 47.13 | N8: r | O8: 47.22 | P8: 0 | Q8: PHILIPPINESRice, Regular Milled | R8: 40.35 | S8: 0 | T8: 40.31 | U8: r | V8: 40.11 | W8: 0 | Y8: PHILIPPINESFresh Beef, Meat with Bones | Z8: 368.26 | AA8: 0 | AB8: 369.64 | AC8: r | AD8: 369.14 | AE8: 0 | AF8: PHILIPPINESFresh Beef, Pure Meat | AG8: 450.37 | AH8: 0 | AI8: 451.47 | AK8: 452.9 | AL8: 0 | AM8: PHILIPPINESFresh Pork, Kasim | AN8: 364.93 | AO8: 0 | AP8: 360.64 | AR8: 358.24 | AS8: 0 | AT8: PHILIPPINESFresh Pork, Liempo | AU8: 385.74 | AV8: 0 | AW8: 381.08 | AY8: 379.19 | AZ8: 0 | BA8: PHILIPPINESFresh Pork, Meat with Bones | BB8: 330.56 | BC8: 0 | BD8: 327.54 | BF8: 327.03 | BG8: 0 | BH8: PHILIPPINESDressed Chicken | BI8: 216.57 | BJ8: 0 | BK8: 215.22 | BM8: 214.49 | BN8: 0 | BO8: PHILIPPINESChicken egg, med. (piece) | BP8: 9.41 | BQ8: 0 | BR8: 9.39 | BT8: 9.4 | BU8: 0 | BW8: PHILIPPINESBangus | BX8: 231.86 | BY8: 0 | BZ8: 238.51 | CB8: 239.61 | CC8: 0 | CD8: PHILIPPINESGalunggong | CE8: 228.08 | CF8: 0 | CG8: 231.11 | CI8: 232.37 | CJ8: 0 | CK8: PHILIPPINESTilapia | CL8: 183.42 | CM8: 0 | CN8: 183.02 | CO8: r | CP8: 182.7 | CQ8: 0 | CS8: PHILIPPINESAmpalaya | CT8: 132.13 | CU8: 0 | CV8: 116.2 | CX8: 115.53 | CY8: 0 | CZ8: PHILIPPINESCabbage | DA8: 134.92 | DB8: 0 | DC8: 123.15 | DE8: 111.26 | DF8: 0 | DG8: PHILIPPINESCarrot | DH8: 176.36 | DI8: 0 | DJ8: 189.62 | DL8: 192.87 | DM8: 0 | DN8: PHILIPPINESEggplant | DO8: 112.94 | DP8: 0 | DQ8: 92.06 | DS8: 89.64 | DT8: 0 | DU8: PHILIPPINESBaguio Beans | DV8: 144.44 | DW8: 0 | DX8: 144 | DZ8: 137.33 | EA8: 0 | EB8: PHILIPPINESPechay, Native | EC8: 125.06 | ED8: 0 | EE8: 120.72 | EF8: r | EG8: 117.66 | EH8: 0 | EI8: PHILIPPINESString Beans | EJ8: 111.47 | EK8: 0 | EL8: 108.81 | EN8: 107.7 | EO8: 0 | EP8: PHILIPPINESTomato | EQ8: 81.88 | ER8: 0 | ES8: 99.6 | EU8: 102.49 | EV8: 0 | EW8: PHILIPPINESWhite Potato | EX8: 119.31 | EY8: 0 | EZ8: 119.88 | FB8: 120.46 | FC8: 0 | FE8: PHILIPPINESOnion, Red | FF8: 175.52 | FG8: 0 | FH8: 179.36 | FJ8: 180.41 | FK8: 0 | FL8: PHILIPPINESGarlic, Native | FM8: 181.7 | FN8: 0 | FO8: 183.33 | FQ8: 182.38 | FR8: 0 | FS8: PHILIPPINESGarlic, Imported | FT8: 169.84 | FU8: 0 | FV8: 167.97 | FX8: 166.39 | FY8: 0 | FZ8: PHILIPPINESGinger, Hawaiian | GA8: 184.25 | GB8: 0 | GC8: 181.5 | GE8: 177.81 | GF8: 0 | GH8: PHILIPPINESBanana, Lakatan | GI8: 92.41 | GJ8: 0 | GK8: 92.16 | GM8: 91.48 | GN8: 0 | GO8: PHILIPPINESBanana, Latundan | GP8: 56.03 | GQ8: 0 | GR8: 54.9 | GT8: 55.28 | GU8: 0 | GV8: PHILIPPINESCalamansi | GW8: 88.59 | GX8: 0 | GY8: 84.18 | HA8: 82.25 | HB8: 0 | HC8: PHILIPPINESMango, Carabao | HD8: 167.29 | HE8: 0 | HF8: 174.04 | HH8: 176.03 | HI8: 0 | HJ8: PHILIPPINESPapaya | HK8: 57.27 | HL8: 0 | HM8: 57.88 | HO8: 57.09 | HP8: 0 | HR8: PHILIPPINESCooking oil | HS8: 184.5 | HT8: 0 | HU8: 186.59 | HW8: 186.68 | HX8: 0 | HY8: PHILIPPINESBrown Sugar | HZ8: 74.5 | IA8: 0 | IB8: 74.22 | ID8: 74.33 | IE8: 0 | IF8: PHILIPPINESRefined Sugar | IG8: 84.57 | IH8: 0 | II8: 83.96 | IJ8: r | IK8: 83.75 | IL8: 0
A9: NCR | B9: NCR- National Capital Region | C9: NCRRice, Special | D9: 56.48 | E9: 0 | F9: 56.43 | H9: 56.34 | I9: 0 | J9: NCRRice, Well Milled | K9: 47.1 | L9: 0 | M9: 47.01 | O9: 46.86 | P9: 0 | Q9: NCRRice, Regular Milled | R9: 39.66 | S9: 0 | T9: 39.75 | V9: 39.65 | W9: 0 | Y9: NCRFresh Beef, Meat with Bones | Z9: 421.25 | AA9: 0 | AB9: 420.93 | AD9: 423.94 | AE9: 0 | AF9: NCRFresh Beef, Pure Meat | AG9: 473.8 | AH9: 0 | AI9: 472.36 | AK9: 473.36 | AL9: 0 | AM9: NCRFresh Pork, Kasim | AN9: 366.97 | AO9: 0 | AP9: 363.77 | AR9: 361.73 | AS9: 0 | AT9: NCRFresh Pork, Liempo | AU9: 414.69 | AV9: 0 | AW9: 409.63 | AY9: 407.06 | AZ9: 0 | BA9: NCRFresh Pork, Meat with Bones | BB9: 345.24 | BC9: 0 | BD9: 343.16 | BF9: 337.03 | BG9: 0 | BH9: NCRDressed Chicken | BI9: 215.43 | BJ9: 0 | BK9: 198.47 | BM9: 209.17 | BN9: 0 | BO9: NCRChicken egg, med. (piece) | BP9: 8.59 | BQ9: 0 | BR9: 8.59 | BT9: 8.66 | BU9: 0 | BW9: NCRBangus | BX9: 255.71 | BY9: 0 | BZ9: 266.86 | CB9: 271.59 | CC9: 0 | CD9: NCRGalunggong | CE9: 296.42 | CF9: 0 | CG9: 307.75 | CI9: 311.66 | CJ9: 0 | CK9: NCRTilapia | CL9: 154.05 | CM9: 0 | CN9: 155.46 | CP9: 157.54 | CQ9: 0 | CS9: NCRAmpalaya | CT9: 145.74 | CU9: 0 | CV9: 120.84 | CX9: 127.5 | CY9: 0 | CZ9: NCRCabbage | DA9: 181.12 | DB9: 0 | DC9: 119.63 | DE9: 96.56 | DF9: 0 | DG9: NCRCarrot | DH9: 247.39 | DI9: 0 | DJ9: 247.77 | DL9: 259.72 | DM9: 0 | DN9: NCREggplant | DO9: 138.55 | DP9: 0 | DQ9: 93.21 | DS9: 100.4 | DT9: 0 | DU9: NCRBaguio Beans | DV9: 173.6 | DW9: 0 | DX9: 149.18 | DZ9: 133.74 | EA9: 0 | EB9: NCRPechay, Native | EC9: 132.55 | ED9: 0 | EE9: 118.1 | EG9: 113 | EH9: 0 | EI9: NCRString Beans | EJ9: 158.08 | EK9: 0 | EL9: 156.32 | EN9: 158.04 | EO9: 0 | EP9: NCRTomato | EQ9: 94.8 | ER9: 0 | ES9: 127.94 | EU9: 115.95 | EV9: 0 | EW9: NCRWhite Potato | EX9: 98.05 | EY9: 0 | EZ9: 101.3 | FB9: 105.61 | FC9: 0 | FE9: NCROnion, Red | FF9: 162.5 | FG9: 0 | FH9: 160.37 | FJ9: 159.77 | FK9: 0 | FL9: NCRGarlic, Native | FM9: 326.02 | FN9: 0 | FO9: 324.42 | FQ9: 325.84 | FR9: 0 | FS9: NCRGarlic, Imported | FT9: 157.01 | FU9: 0 | FV9: 157.1 | FX9: 155.47 | FY9: 0 | FZ9: NCRGinger, Hawaiian | GA9: 196.98 | GB9: 0 | GC9: 193.62 | GE9: 192.37 | GF9: 0 | GH9: NCRBanana, Lakatan | GI9: 98.95 | GJ9: 0 | GK9: 99 | GM9: 98.13 | GN9: 0 | GO9: NCRBanana, Latundan | GP9: 0 | GQ9: 0 | GR9: 0 | GT9: 0 | GU9: 0 | GV9: NCRCalamansi | GW9: 88.8 | GX9: 0 | GY9: 82.79 | HA9: 77.5 | HB9: 0 | HC9: NCRMango, Carabao | HD9: 179.99 | HE9: 0 | HF9: 189.44 | HH9: 191.41 | HI9: 0 | HJ9: NCRPapaya | HK9: 0 | HL9: 0 | HM9: 0 | HO9: 0 | HP9: 0 | HR9: NCRCooking oil | HS9: 187.61 | HT9: 0 | HU9: 190.08 | HW9: 190.99 | HX9: 0 | HY9: NCRBrown Sugar | HZ9: 82.13 | IA9: 0 | IB9: 82.21 | ID9: 82.02 | IE9: 0 | IF9: NCRRefined Sugar | IG9: 92.86 | IH9: 0 | II9: 92.98 | IK9: 92.77 | IL9: 0
A10: CAR | B10: CAR - Cordillera Administrative Region | C10: CARRice, Special | D10: 56.6 | E10: 0 | F10: 56.35 | H10: 57.41 | I10: 0 | J10: CARRice, Well Milled | K10: 46.64 | L10: 0 | M10: 46.05 | O10: 47.25 | P10: 0 | Q10: CARRice, Regular Milled | R10: 40.24 | S10: 0 | T10: 39.76 | V10: 40.74 | W10: 0 | Y10: CARFresh Beef, Meat with Bones | Z10: 390.48 | AA10: 0 | AB10: 391.05 | AD10: 391.05 | AE10: 0 | AF10: CARFresh Beef, Pure Meat | AG10: 411.43 | AH10: 0 | AI10: 414.63 | AK10: 414.47 | AL10: 0 | AM10: CARFresh Pork, Kasim | AN10: 363.71 | AO10: 0 | AP10: 362.64 | AR10: 354.79 | AS10: 0 | AT10: CARFresh Pork, Liempo | AU10: 373.12 | AV10: 0 | AW10: 372.64 | AY10: 364.9 | AZ10: 0 | BA10: CARFresh Pork, Meat with Bones | BB10: 355.67 | BC10: 0 | BD10: 354.48 | BF10: 350.81 | BG10: 0 | BH10: CARDressed Chicken | BI10: 235.29 | BJ10: 0 | BK10: 235.55 | BM10: 231.14 | BN10: 0 | BO10: CARChicken egg, med. (piece) | BP10: 9.24 | BQ10: 0 | BR10: 9.28 | BT10: 9.27 | BU10: 0 | BW10: CARBangus | BX10: 231.43 | BY10: 0 | BZ10: 238.81 | CB10: 235.83 | CC10: 0 | CD10: CARGalunggong | CE10: 237.36 | CF10: 0 | CG10: 239.26 | CI10: 239.98 | CJ10: 0 | CK10: CARTilapia | CL10: 181.38 | CM10: 0 | CN10: 180.81 | CP10: 178.67 | CQ10: 0 | CS10: CARAmpalaya | CT10: 120.42 | CU10: 0 | CV10: 109.73 | CX10: 106.88 | CY10: 0 | CZ10: CARCabbage | DA10: 98.9 | DB10: 0 | DC10: 98.23 | DE10: 85.02 | DF10: 0 | DG10: CARCarrot | DH10: 120.24 | DI10: 0 | DJ10: 142.64 | DL10: 149.45 | DM10: 0 | DN10: CAREggplant | DO10: 98.39 | DP10: 0 | DQ10: 79.21 | DS10: 78.63 | DT10: 0 | DU10: CARBaguio Beans | DV10: 128.94 | DW10: 0 | DX10: 122.04 | DZ10: 116.23 | EA10: 0 | EB10: CARPechay, Native | EC10: 35 | ED10: 0 | EE10: 30 | EG10: 35 | EH10: 0 | EI10: CARString Beans | EJ10: 107.52 | EK10: 0 | EL10: 101.54 | EN10: 97.82 | EO10: 0 | EP10: CARTomato | EQ10: 71.3 | ER10: 0 | ES10: 87.27 | EU10: 83.77 | EV10: 0 | EW10: CARWhite Potato | EX10: 85.15 | EY10: 0 | EZ10: 85.99 | FB10: 91.18 | FC10: 0 | FE10: CAROnion, Red | FF10: 166.29 | FG10: 0 | FH10: 168.31 | FJ10: 169.74 | FK10: 0 | FL10: CARGarlic, Native | FM10: 195.13 | FN10: 0 | FO10: 193.71 | FQ10: 185 | FR10: 0 | FS10: CARGarlic, Imported | FT10: 143.75 | FU10: 0 | FV10: 145 | FX10: 147.5 | FY10: 0 | FZ10: CARGinger, Hawaiian | GA10: 164.01 | GB10: 0 | GC10: 163.51 | GE10: 160.09 | GF10: 0 | GH10: CARBanana, Lakatan | GI10: 107.61 | GJ10: 0 | GK10: 108.25 | GM10: 107.7 | GN10: 0 | GO10: CARBanana, Latundan | GP10: 58.6 | GQ10: 0 | GR10: 58.8 | GT10: 58.8 | GU10: 0 | GV10: CARCalamansi | GW10: 108.91 | GX10: 0 | GY10: 102.99 | HA10: 100.99 | HB10: 0 | HC10: CARMango, Carabao | HD10: 82.5 | HE10: 0 | HF10: 82.5 | HH10: 82.5 | HI10: 0 | HJ10: CARPapaya | HK10: 61.38 | HL10: 0 | HM10: 60.75 | HO10: 62 | HP10: 0 | HR10: CARCooking oil | HS10: 133 | HT10: 0 | HU10: 133 | HW10: 133 | HX10: 0 | HY10: CARBrown Sugar | HZ10: 72.8 | IA10: 0 | IB10: 72.43 | ID10: 72.41 | IE10: 0 | IF10: CARRefined Sugar | IG10: 83.6 | IH10: 0 | II10: 82.81 | IK10: 82.88 | IL10: 0
A11: 1 | B11: Abra | C11: 1Rice, Special | D11: 58 | E11: 0 | F11: 58 | H11: 58 | I11: 0 | J11: 1Rice, Well Milled | K11: 50 | L11: 0 | M11: 50 | O11: 50 | P11: 0 | Q11: 1Rice, Regular Milled | R11: 36.5 | S11: 0 | T11: 36.25 | V11: 36.5 | W11: 0 | Y11: 1Fresh Beef, Meat with Bones | Z11: 320 | AA11: 0 | AB11: 320 | AD11: 320 | AE11: 0 | AF11: 1Fresh Beef, Pure Meat | AG11: 350 | AH11: 0 | AI11: 350 | AK11: 350 | AL11: 0 | AM11: 1Fresh Pork, Kasim | AN11: 335 | AO11: 0 | AP11: 335 | AR11: 335 | AS11: 0 | AT11: 1Fresh Pork, Liempo | AU11: 320 | AV11: 0 | AW11: 320 | AY11: 320 | AZ11: 0 | BA11: 1Fresh Pork, Meat with Bones | BB11: 310 | BC11: 0 | BD11: 310 | BF11: 310 | BG11: 0 | BH11: 1Dressed Chicken | BI11: 240 | BJ11: 0 | BK11: 240 | BM11: 240 | BN11: 0 | BO11: 1Chicken egg, med. (piece) | BP11: 8 | BQ11: 0 | BR11: 8 | BT11: 8 | BU11: 0 | BW11: 1Bangus | BX11: 205 | BY11: 0 | BZ11: 205 | CB11: 205 | CC11: 0 | CD11: 1Galunggong | CE11: 225 | CF11: 0 | CG11: 225 | CI11: 225 | CJ11: 0 | CK11: 1Tilapia | CL11: 200 | CM11: 0 | CN11: 200 | CP11: 200 | CQ11: 0 | CS11: 1Ampalaya | CT11: 100 | CU11: 0 | CV11: 100 | CX11: 120 | CY11: 0 | CZ11: 1Cabbage | DA11: 90 | DB11: 0 | DC11: 110 | DE11: 95 | DF11: 0 | DG11: 1Carrot | DH11: 130 | DI11: 0 | DJ11: 140 | DL11: 155 | DM11: 0 | DN11: 1Eggplant | DO11: 100 | DP11: 0 | DQ11: 95 | DS11: 90 | DT11: 0 | DU11: 1Baguio Beans | DV11: 0 | DW11: 0 | DX11: 0 | DZ11: 0 | EA11: 0 | EB11: 1Pechay, Native | EC11: 0 | ED11: 0 | EE11: 0 | EG11: 0 | EH11: 0 | EI11: 1String Beans | EJ11: 135 | EK11: 0 | EL11: 135 | EN11: 120 | EO11: 0 | EP11: 1Tomato | EQ11: 55 | ER11: 0 | ES11: 80 | EU11: 90 | EV11: 0 | EW11: 1White Potato | EX11: 100 | EY11: 0 | EZ11: 100 | FB11: 110 | FC11: 0 | FE11: 1Onion, Red | FF11: 150 | FG11: 0 | FH11: 150 | FJ11: 150 | FK11: 0 | FL11: 1Garlic, Native | FM11: 155 | FN11: 0 | FO11: 155 | FQ11: 155 | FR11: 0 | FS11: 1Garlic, Imported | FT11: 0 | FU11: 0 | FV11: 0 | FX11: 0 | FY11: 0 | FZ11: 1Ginger, Hawaiian | GA11: 170 | GB11: 0 | GC11: 170 | GE11: 160 | GF11: 0 | GH11: 1Banana, Lakatan | GI11: 135 | GJ11: 0 | GK11: 135 | GM11: 125 | GN11: 0 | GO11: 1Banana, Latundan | GP11: 80 | GQ11: 0 | GR11: 80 | GT11: 80 | GU11: 0 | GV11: 1Calamansi | GW11: 100 | GX11: 0 | GY11: 90 | HA11: 85 | HB11: 0 | HC11: 1Mango, Carabao | HD11: 55 | HE11: 0 | HF11: 55 | HH11: 55 | HI11: 0 | HJ11: 1Papaya | HK11: 45 | HL11: 0 | HM11: 45 | HO11: 45 | HP11: 0 | HR11: 1Cooking oil | HS11: 0 | HT11: 0 | HU11: 0 | HW11: 0 | HX11: 0 | HY11: 1Brown Sugar | HZ11: 76.5 | IA11: 0 | IB11: 76.5 | ID11: 76.5 | IE11: 0 | IF11: 1Refined Sugar | IG11: 0 | IH11: 0 | II11: 0 | IK11: 0 | IL11: 0
A12: 81 | B12: Apayao | C12: 81Rice, Special | D12: 51.5 | E12: 0 | F12: 54 | H12: 54 | I12: 0 | J12: 81Rice, Well Milled | K12: 32.1 | L12: 0 | M12: 32.9 | O12: 32.9 | P12: 0 | Q12: 81Rice, Regular Milled | R12: 31 | S12: 0 | T12: 32 | V12: 32 | W12: 0 | Y12: 81Fresh Beef, Meat with Bones | Z12: 375 | AA12: 0 | AB12: 380 | AD12: 380 | AE12: 0 | AF12: 81Fresh Beef, Pure Meat | AG12: 400 | AH12: 0 | AI12: 405 | AK12: 405 | AL12: 0 | AM12: 81Fresh Pork, Kasim | AN12: 350 | AO12: 0 | AP12: 350 | AR12: 350 | AS12: 0 | AT12: 81Fresh Pork, Liempo | AU12: 350 | AV12: 0 | AW12: 350 | AY12: 350 | AZ12: 0 | BA12: 81Fresh Pork, Meat with Bones | BB12: 340 | BC12: 0 | BD12: 340 | BF12: 340 | BG12: 0 | BH12: 81Dressed Chicken | BI12: 240 | BJ12: 0 | BK12: 235 | BM12: 235 | BN12: 0 | BO12: 81Chicken egg, med. (piece) | BP12: 9.13 | BQ12: 0 | BR12: 9.13 | BT12: 9.13 | BU12: 0 | BW12: 81Bangus | BX12: 225 | BY12: 0 | BZ12: 245 | CB12: 245 | CC12: 0 | CD12: 81Galunggong | CE12: 210 | CF12: 0 | CG12: 210 | CI12: 210 | CJ12: 0 | CK12: 81Tilapia | CL12: 185 | CM12: 0 | CN12: 185 | CP12: 185 | CQ12: 0 | CS12: 81Ampalaya | CT12: 85 | CU12: 0 | CV12: 90 | CX12: 90 | CY12: 0 | CZ12: 81Cabbage | DA12: 110 | DB12: 0 | DC12: 90 | DE12: 90 | DF12: 0 | DG12: 81Carrot | DH12: 150 | DI12: 0 | DJ12: 175 | DL12: 175 | DM12: 0 | DN12: 81Eggplant | DO12: 110 | DP12: 0 | DQ12: 90 | DS12: 90 | DT12: 0 | DU12: 81Baguio Beans | DV12: 0 | DW12: 0 | DX12: 0 | DZ12: 0 | EA12: 0 | EB12: 81Pechay, Native | EC12: 0 | ED12: 0 | EE12: 0 | EG12: 0 | EH12: 0 | EI12: 81String Beans | EJ12: 90 | EK12: 0 | EL12: 95 | EN12: 95 | EO12: 0 | EP12: 81Tomato | EQ12: 60 | ER12: 0 | ES12: 65 | EU12: 65 | EV12: 0 | EW12: 81White Potato | EX12: 87.5 | EY12: 0 | EZ12: 80 | FB12: 80 | FC12: 0 | FE12: 81Onion, Red | FF12: 160 | FG12: 0 | FH12: 165 | FJ12: 165 | FK12: 0 | FL12: 81Garlic, Native | FM12: 0 | FN12: 0 | FO12: 0 | FQ12: 0 | FR12: 0 | FS12: 81Garlic, Imported | FT12: 145 | FU12: 0 | FV12: 145 | FX12: 145 | FY12: 0 | FZ12: 81Ginger, Hawaiian | GA12: 140 | GB12: 0 | GC12: 150 | GE12: 150 | GF12: 0 | GH12: 81Banana, Lakatan | GI12: 70 | GJ12: 0 | GK12: 72.5 | GM12: 72.5 | GN12: 0 | GO12: 81Banana, Latundan | GP12: 37.5 | GQ12: 0 | GR12: 40 | GT12: 40 | GU12: 0 | GV12: 81Calamansi | GW12: 72.5 | GX12: 0 | GY12: 80 | HA12: 80 | HB12: 0 | HC12: 81Mango, Carabao | HD12: 0 | HE12: 0 | HF12: 0 | HH12: 0 | HI12: 0 | HJ12: 81Papaya | HK12: 0 | HL12: 0 | HM12: 0 | HO12: 0 | HP12: 0 | HR12: 81Cooking oil | HS12: 0 | HT12: 0 | HU12: 0 | HW12: 0 | HX12: 0 | HY12: 81Brown Sugar | HZ12: 70 | IA12: 0 | IB12: 70 | ID12: 70 | IE12: 0 | IF12: 81Refined Sugar | IG12: 89.5 | IH12: 0 | II12: 89.5 | IK12: 89.5 | IL12: 0
A13: 11 | B13: Benguet | C13: 11Rice, Special | D13: 54.67 | E13: 0 | F13: 54.67 | H13: 54.67 | I13: 0 | J13: 11Rice, Well Milled | K13: 48.67 | L13: 0 | M13: 48.67 | O13: 48.67 | P13: 0 | Q13: 11Rice, Regular Milled | R13: 43.5 | S13: 0 | T13: 43.5 | V13: 43.5 | W13: 0 | Y13: 11Fresh Beef, Meat with Bones | Z13: 438.5 | AA13: 0 | AB13: 444 | AD13: 444 | AE13: 0 | AF13: 11Fresh Beef, Pure Meat | AG13: 441.5 | AH13: 0 | AI13: 447.5 | AK13: 447.5 | AL13: 0 | AM13: 11Fresh Pork, Kasim | AN13: 324 | AO13: 0 | AP13: 324 | AR13: 324 | AS13: 0 | AT13: 11Fresh Pork, Liempo | AU13: 359 | AV13: 0 | AW13: 359 | AY13: 359 | AZ13: 0 | BA13: 11Fresh Pork, Meat with Bones | BB13: 299 | BC13: 0 | BD13: 299 | BF13: 299 | BG13: 0 | BH13: 11Dressed Chicken | BI13: 204 | BJ13: 0 | BK13: 205 | BM13: 205 | BN13: 0 | BO13: 11Chicken egg, med. (piece) | BP13: 9.25 | BQ13: 0 | BR13: 9.38 | BT13: 9.38 | BU13: 0 | BW13: 11Bangus | BX13: 230 | BY13: 0 | BZ13: 245 | CB13: 225 | CC13: 0 | CD13: 11Galunggong | CE13: 245 | CF13: 0 | CG13: 245 | CI13: 245 | CJ13: 0 | CK13: 11Tilapia | CL13: 175 | CM13: 0 | CN13: 175 | CP13: 165 | CQ13: 0 | CS13: 11Ampalaya | CT13: 115 | CU13: 0 | CV13: 100 | CX13: 95 | CY13: 0 | CZ13: 11Cabbage | DA13: 82.5 | DB13: 0 | DC13: 84 | DE13: 79 | DF13: 0 | DG13: 11Carrot | DH13: 115 | DI13: 0 | DJ13: 155 | DL13: 165 | DM13: 0 | DN13: 11Eggplant | DO13: 110 | DP13: 0 | DQ13: 68 | DS13: 65 | DT13: 0 | DU13: 11Baguio Beans | DV13: 145 | DW13: 0 | DX13: 145 | DZ13: 125 | EA13: 0 | EB13: 11Pechay, Native | EC13: 0 | ED13: 0 | EE13: 0 | EG13: 0 | EH13: 0 | EI13: 11String Beans | EJ13: 120 | EK13: 0 | EL13: 99.5 | EN13: 99.5 | EO13: 0 | EP13: 11Tomato | EQ13: 70 | ER13: 0 | ES13: 99.5 | EU13: 95 | EV13: 0 | EW13: 11White Potato | EX13: 80 | EY13: 0 | EZ13: 89 | FB13: 80 | FC13: 0 | FE13: 11Onion, Red | FF13: 185 | FG13: 0 | FH13: 182 | FJ13: 182 | FK13: 0 | FL13: 11Garlic, Native | FM13: 250 | FN13: 0 | FO13: 239 | FQ13: 230 | FR13: 0 | FS13: 11Garlic, Imported | FT13: 0 | FU13: 0 | FV13: 0 | FX13: 0 | FY13: 0 | FZ13: 11Ginger, Hawaiian | GA13: 180 | GB13: 0 | GC13: 170 | GE13: 165 | GF13: 0 | GH13: 11Banana, Lakatan | GI13: 101.5 | GJ13: 0 | GK13: 101.5 | GM13: 101.5 | GN13: 0 | GO13: 11Banana, Latundan | GP13: 0 | GQ13: 0 | GR13: 0 | GT13: 0 | GU13: 0 | GV13: 11Calamansi | GW13: 135 | GX13: 0 | GY13: 109 | HA13: 120 | HB13: 0 | HC13: 11Mango, Carabao | HD13: 0 | HE13: 0 | HF13: 0 | HH13: 0 | HI13: 0 | HJ13: 11Papaya | HK13: 50 | HL13: 0 | HM13: 50 | HO13: 55 | HP13: 0 | HR13: 11Cooking oil | HS13: 0 | HT13: 0 | HU13: 0 | HW13: 0 | HX13: 0 | HY13: 11Brown Sugar | HZ13: 77.25 | IA13: 0 | IB13: 76.13 | ID13: 76.13 | IE13: 0 | IF13: 11Refined Sugar | IG13: 90.75 | IH13: 0 | II13: 87.5 | IK13: 87.5 | IL13: 0
A14: 27 | B14: Ifugao | C14: 27Rice, Special | D14: 0 | E14: 0 | F14: 0 | H14: 0 | I14: 0 | J14: 27Rice, Well Milled | K14: 42.2 | L14: 0 | M14: 42.1 | O14: 42.1 | P14: 0 | Q14: 27Rice, Regular Milled | R14: 40 | S14: 0 | T14: 40 | V14: 40 | W14: 0 | Y14: 27Fresh Beef, Meat with Bones | Z14: 380 | AA14: 0 | AB14: 380 | AD14: 380 | AE14: 0 | AF14: 27Fresh Beef, Pure Meat | AG14: 380 | AH14: 0 | AI14: 380 | AK14: 380 | AL14: 0 | AM14: 27Fresh Pork, Kasim | AN14: 400 | AO14: 0 | AP14: 400 | AR14: 400 | AS14: 0 | AT14: 27Fresh Pork, Liempo | AU14: 400 | AV14: 0 | AW14: 400 | AY14: 400 | AZ14: 0 | BA14: 27Fresh Pork, Meat with Bones | BB14: 400 | BC14: 0 | BD14: 400 | BF14: 400 | BG14: 0 | BH14: 27Dressed Chicken | BI14: 260 | BJ14: 0 | BK14: 260 | BM14: 250 | BN14: 0 | BO14: 27Chicken egg, med. (piece) | BP14: 9 | BQ14: 0 | BR14: 9 | BT14: 9 | BU14: 0 | BW14: 27Bangus | BX14: 290 | BY14: 0 | BZ14: 300 | CB14: 300 | CC14: 0 | CD14: 27Galunggong | CE14: 250 | CF14: 0 | CG14: 250 | CI14: 250 | CJ14: 0 | CK14: 27Tilapia | CL14: 180 | CM14: 0 | CN14: 180 | CP14: 180 | CQ14: 0 | CS14: 27Ampalaya | CT14: 125 | CU14: 0 | CV14: 105 | CX14: 105 | CY14: 0 | CZ14: 27Cabbage | DA14: 125 | DB14: 0 | DC14: 105 | DE14: 75 | DF14: 0 | DG14: 27Carrot | DH14: 140 | DI14: 0 | DJ14: 180 | DL14: 165 | DM14: 0 | DN14: 27Eggplant | DO14: 100 | DP14: 0 | DQ14: 55 | DS14: 75 | DT14: 0 | DU14: 27Baguio Beans | DV14: 105 | DW14: 0 | DX14: 85 | DZ14: 85 | EA14: 0 | EB14: 27Pechay, Native | EC14: 0 | ED14: 0 | EE14: 0 | EG14: 0 | EH14: 0 | EI14: 27String Beans | EJ14: 0 | EK14: 0 | EL14: 0 | EN14: 0 | EO14: 0 | EP14: 27Tomato | EQ14: 65 | ER14: 0 | ES14: 85 | EU14: 85 | EV14: 0 | EW14: 27White Potato | EX14: 80 | EY14: 0 | EZ14: 82.5 | FB14: 100 | FC14: 0 | FE14: 27Onion, Red | FF14: 170 | FG14: 0 | FH14: 170 | FJ14: 180 | FK14: 0 | FL14: 27Garlic, Native | FM14: 170 | FN14: 0 | FO14: 170 | FQ14: 165 | FR14: 0 | FS14: 27Garlic, Imported | FT14: 0 | FU14: 0 | FV14: 0 | FX14: 0 | FY14: 0 | FZ14: 27Ginger, Hawaiian | GA14: 130 | GB14: 0 | GC14: 125 | GE14: 125 | GF14: 0 | GH14: 27Banana, Lakatan | GI14: 100 | GJ14: 0 | GK14: 100 | GM14: 100 | GN14: 0 | GO14: 27Banana, Latundan | GP14: 85 | GQ14: 0 | GR14: 85 | GT14: 85 | GU14: 0 | GV14: 27Calamansi | GW14: 105 | GX14: 0 | GY14: 105 | HA14: 85 | HB14: 0 | HC14: 27Mango, Carabao | HD14: 0 | HE14: 0 | HF14: 0 | HH14: 0 | HI14: 0 | HJ14: 27Papaya | HK14: 70 | HL14: 0 | HM14: 70 | HO14: 70 | HP14: 0 | HR14: 27Cooking oil | HS14: 133 | HT14: 0 | HU14: 133 | HW14: 133 | HX14: 0 | HY14: 27Brown Sugar | HZ14: 72 | IA14: 0 | IB14: 72 | ID14: 72 | IE14: 0 | IF14: 27Refined Sugar | IG14: 80 | IH14: 0 | II14: 80 | IK14: 80 | IL14: 0
A15: 32 | B15: Kalinga | C15: 32Rice, Special | D15: 48.5 | E15: 0 | F15: 46.5 | H15: 46.5 | I15: 0 | J15: 32Rice, Well Milled | K15: 41.5 | L15: 0 | M15: 39 | O15: 39 | P15: 0 | Q15: 32Rice, Regular Milled | R15: 37 | S15: 0 | T15: 35 | V15: 35 | W15: 0 | Y15: 32Fresh Beef, Meat with Bones | Z15: 400 | AA15: 0 | AB15: 400 | AD15: 400 | AE15: 0 | AF15: 32Fresh Beef, Pure Meat | AG15: 0 | AH15: 0 | AI15: 0 | AK15: 0 | AL15: 0 | AM15: 32Fresh Pork, Kasim | AN15: 390 | AO15: 0 | AP15: 380 | AR15: 375 | AS15: 0 | AT15: 32Fresh Pork, Liempo | AU15: 390 | AV15: 0 | AW15: 380 | AY15: 375 | AZ15: 0 | BA15: 32Fresh Pork, Meat with Bones | BB15: 380 | BC15: 0 | BD15: 370 | BF15: 365 | BG15: 0 | BH15: 32Dressed Chicken | BI15: 225 | BJ15: 0 | BK15: 232.5 | BM15: 227.5 | BN15: 0 | BO15: 32Chicken egg, med. (piece) | BP15: 0 | BQ15: 0 | BR15: 0 | BT15: 0 | BU15: 0 | BW15: 32Bangus | BX15: 202.5 | BY15: 0 | BZ15: 195 | CB15: 205 | CC15: 0 | CD15: 32Galunggong | CE15: 205 | CF15: 0 | CG15: 205 | CI15: 210 | CJ15: 0 | CK15: 32Tilapia | CL15: 165 | CM15: 0 | CN15: 165 | CP15: 165 | CQ15: 0 | CS15: 32Ampalaya | CT15: 85 | CU15: 0 | CV15: 70 | CX15: 80 | CY15: 0 | CZ15: 32Cabbage | DA15: 90 | DB15: 0 | DC15: 90 | DE15: 62.5 | DF15: 0 | DG15: 32Carrot | DH15: 85 | DI15: 0 | DJ15: 90 | DL15: 120 | DM15: 0 | DN15: 32Eggplant | DO15: 45 | DP15: 0 | DQ15: 35 | DS15: 42.5 | DT15: 0 | DU15: 32Baguio Beans | DV15: 100 | DW15: 0 | DX15: 100 | DZ15: 105 | EA15: 0 | EB15: 32Pechay, Native | EC15: 35 | ED15: 0 | EE15: 30 | EG15: 35 | EH15: 0 | EI15: 32String Beans | EJ15: 57.5 | EK15: 0 | EL15: 50 | EN15: 52.5 | EO15: 0 | EP15: 32Tomato | EQ15: 45 | ER15: 0 | ES15: 60 | EU15: 70 | EV15: 0 | EW15: 32White Potato | EX15: 75 | EY15: 0 | EZ15: 70 | FB15: 75 | FC15: 0 | FE15: 32Onion, Red | FF15: 135 | FG15: 0 | FH15: 145 | FJ15: 150 | FK15: 0 | FL15: 32Garlic, Native | FM15: 0 | FN15: 0 | FO15: 0 | FQ15: 0 | FR15: 0 | FS15: 32Garlic, Imported | FT15: 142.5 | FU15: 0 | FV15: 145 | FX15: 150 | FY15: 0 | FZ15: 32Ginger, Hawaiian | GA15: 160 | GB15: 0 | GC15: 152.5 | GE15: 150 | GF15: 0 | GH15: 32Banana, Lakatan | GI15: 0 | GJ15: 0 | GK15: 0 | GM15: 0 | GN15: 0 | GO15: 32Banana, Latundan | GP15: 33 | GQ15: 0 | GR15: 31.5 | GT15: 31.5 | GU15: 0 | GV15: 32Calamansi | GW15: 72.5 | GX15: 0 | GY15: 62.5 | HA15: 62.5 | HB15: 0 | HC15: 32Mango, Carabao | HD15: 0 | HE15: 0 | HF15: 0 | HH15: 0 | HI15: 0 | HJ15: 32Papaya | HK15: 0 | HL15: 0 | HM15: 0 | HO15: 0 | HP15: 0 | HR15: 32Cooking oil | HS15: 0 | HT15: 0 | HU15: 0 | HW15: 0 | HX15: 0 | HY15: 32Brown Sugar | HZ15: 69 | IA15: 0 | IB15: 67.5 | ID15: 68.5 | IE15: 0 | IF15: 32Refined Sugar | IG15: 78 | IH15: 0 | II15: 76.5 | IK15: 77.5 | IL15: 0
A16: 44 | B16: Mountain Province | C16: 44Rice, Special | D16: 65.5 | E16: 0 | F16: 63.25 | H16: 69.5 | I16: 0 | J16: 44Rice, Well Milled | K16: 59.5 | L16: 0 | M16: 58.25 | O16: 66.5 | P16: 0 | Q16: 44Rice, Regular Milled | R16: 48 | S16: 0 | T16: 46 | V16: 52.5 | W16: 0 | Y16: 44Fresh Beef, Meat with Bones | Z16: 390 | AA16: 0 | AB16: 370 | AD16: 370 | AE16: 0 | AF16: 44Fresh Beef, Pure Meat | AG16: 0 | AH16: 0 | AI16: 0 | AK16: 0 | AL16: 0 | AM16: 44Fresh Pork, Kasim | AN16: 400 | AO16: 0 | AP16: 400 | AR16: 350 | AS16: 0 | AT16: 44Fresh Pork, Liempo | AU16: 400 | AV16: 0 | AW16: 400 | AY16: 350 | AZ16: 0 | BA16: 44Fresh Pork, Meat with Bones | BB16: 400 | BC16: 0 | BD16: 400 | BF16: 380 | BG16: 0 | BH16: 44Dressed Chicken | BI16: 255 | BJ16: 0 | BK16: 255 | BM16: 240 | BN16: 0 | BO16: 44Chicken egg, med. (piece) | BP16: 11 | BQ16: 0 | BR16: 11 | BT16: 11 | BU16: 0 | BW16: 44Bangus | BX16: 245 | BY16: 0 | BZ16: 245 | CB16: 245 | CC16: 0 | CD16: 44Galunggong | CE16: 225 | CF16: 0 | CG16: 225 | CI16: 225 | CJ16: 0 | CK16: 44Tilapia | CL16: 197.5 | CM16: 0 | CN16: 197.5 | CP16: 197.5 | CQ16: 0 | CS16: 44Ampalaya | CT16: 190 | CU16: 0 | CV16: 190 | CX16: 140 | CY16: 0 | CZ16: 44Cabbage | DA16: 100 | DB16: 0 | DC16: 110 | DE16: 100 | DF16: 0 | DG16: 44Carrot | DH16: 120 | DI16: 0 | DJ16: 120 | DL16: 125 | DM16: 0 | DN16: 44Eggplant | DO16: 120 | DP16: 0 | DQ16: 120 | DS16: 90 | DT16: 0 | DU16: 44Baguio Beans | DV16: 165 | DW16: 0 | DX16: 145 | DZ16: 135 | EA16: 0 | EB16: 44Pechay, Native | EC16: 0 | ED16: 0 | EE16: 0 | EG16: 0 | EH16: 0 | EI16: 44String Beans | EJ16: 120 | EK16: 0 | EL16: 120 | EN16: 110 | EO16: 0 | EP16: 44Tomato | EQ16: 130 | ER16: 0 | ES16: 130 | EU16: 90 | EV16: 0 | EW16: 44White Potato | EX16: 80 | EY16: 0 | EZ16: 80 | FB16: 100 | FC16: 0 | FE16: 44Onion, Red | FF16: 200 | FG16: 0 | FH16: 200 | FJ16: 200 | FK16: 0 | FL16: 44Garlic, Native | FM16: 0 | FN16: 0 | FO16: 0 | FQ16: 0 | FR16: 0 | FS16: 44Garlic, Imported | FT16: 0 | FU16: 0 | FV16: 0 | FX16: 0 | FY16: 0 | FZ16: 44Ginger, Hawaiian | GA16: 200 | GB16: 0 | GC16: 200 | GE16: 200 | GF16: 0 | GH16: 44Banana, Lakatan | GI16: 110 | GJ16: 0 | GK16: 110 | GM16: 120 | GN16: 0 | GO16: 44Banana, Latundan | GP16: 57.5 | GQ16: 0 | GR16: 57.5 | GT16: 57.5 | GU16: 0 | GV16: 44Calamansi | GW16: 180 | GX16: 0 | GY16: 180 | HA16: 180 | HB16: 0 | HC16: 44Mango, Carabao | HD16: 110 | HE16: 0 | HF16: 110 | HH16: 110 | HI16: 0 | HJ16: 44Papaya | HK16: 0 | HL16: 0 | HM16: 0 | HO16: 0 | HP16: 0 | HR16: 44Cooking oil | HS16: 0 | HT16: 0 | HU16: 0 | HW16: 0 | HX16: 0 | HY16: 44Brown Sugar | HZ16: 72.5 | IA16: 0 | IB16: 72.5 | ID16: 72.5 | IE16: 0 | IF16: 44Refined Sugar | IG16: 82.5 | IH16: 0 | II16: 82.5 | IK16: 82.5 | IL16: 0
A17: 1102 | B17: City of Baguio | C17: 1102Rice, Special | D17: 61.44 | E17: 0 | F17: 61.67 | H17: 61.8 | I17: 0 | J17: 1102Rice, Well Milled | K17: 52.53 | L17: 0 | M17: 51.45 | O17: 51.58 | P17: 0 | Q17: 1102Rice, Regular Milled | R17: 45.67 | S17: 0 | T17: 45.58 | V17: 45.67 | W17: 0 | Y17: 1102Fresh Beef, Meat with Bones | Z17: 429.83 | AA17: 0 | AB17: 443.33 | AD17: 443.33 | AE17: 0 | AF17: 1102Fresh Beef, Pure Meat | AG17: 485.67 | AH17: 0 | AI17: 490.67 | AK17: 489.83 | AL17: 0 | AM17: 1102Fresh Pork, Kasim | AN17: 347 | AO17: 0 | AP17: 349.5 | AR17: 349.5 | AS17: 0 | AT17: 1102Fresh Pork, Liempo | AU17: 392.83 | AV17: 0 | AW17: 399.5 | AY17: 400.33 | AZ17: 0 | BA17: 1102Fresh Pork, Meat with Bones | BB17: 360.67 | BC17: 0 | BD17: 362.33 | BF17: 361.67 | BG17: 0 | BH17: 1102Dressed Chicken | BI17: 223 | BJ17: 0 | BK17: 221.33 | BM17: 220.5 | BN17: 0 | BO17: 1102Chicken egg, med. (piece) | BP17: 9.06 | BQ17: 0 | BR17: 9.15 | BT17: 9.13 | BU17: 0 | BW17: 1102Bangus | BX17: 222.5 | BY17: 0 | BZ17: 236.67 | CB17: 225.83 | CC17: 0 | CD17: 1102Galunggong | CE17: 301.5 | CF17: 0 | CG17: 314.83 | CI17: 314.83 | CJ17: 0 | CK17: 1102Tilapia | CL17: 167.17 | CM17: 0 | CN17: 163.17 | CP17: 158.17 | CQ17: 0 | CS17: 1102Ampalaya | CT17: 142.92 | CU17: 0 | CV17: 113.13 | CX17: 118.13 | CY17: 0 | CZ17: 1102Cabbage | DA17: 94.83 | DB17: 0 | DC17: 98.58 | DE17: 93.63 | DF17: 0 | DG17: 1102Carrot | DH17: 101.71 | DI17: 0 | DJ17: 138.46 | DL17: 141.17 | DM17: 0 | DN17: 1102Eggplant | DO17: 103.71 | DP17: 0 | DQ17: 91.46 | DS17: 97.92 | DT17: 0 | DU17: 1102Baguio Beans | DV17: 129.71 | DW17: 0 | DX17: 135.21 | DZ17: 131.13 | EA17: 0 | EB17: 1102Pechay, Native | EC17: 0 | ED17: 0 | EE17: 0 | EG17: 0 | EH17: 0 | EI17: 1102String Beans | EJ17: 122.63 | EK17: 0 | EL17: 109.71 | EN17: 109.92 | EO17: 0 | EP17: 1102Tomato | EQ17: 74.1 | ER17: 0 | ES17: 91.4 | EU17: 91.4 | EV17: 0 | EW17: 1102White Potato | EX17: 93.54 | EY17: 0 | EZ17: 100.42 | FB17: 93.29 | FC17: 0 | FE17: 1102Onion, Red | FF17: 164 | FG17: 0 | FH17: 166.17 | FJ17: 161.17 | FK17: 0 | FL17: 1102Garlic, Native | FM17: 205.5 | FN17: 0 | FO17: 210.83 | FQ17: 190 | FR17: 0 | FS17: 1102Garlic, Imported | FT17: 0 | FU17: 0 | FV17: 0 | FX17: 0 | FY17: 0 | FZ17: 1102Ginger, Hawaiian | GA17: 168.1 | GB17: 0 | GC17: 177.1 | GE17: 170.6 | GF17: 0 | GH17: 1102Banana, Lakatan | GI17: 129.17 | GJ17: 0 | GK17: 130.5 | GM17: 127.17 | GN17: 0 | GO17: 1102Banana, Latundan | GP17: 0 | GQ17: 0 | GR17: 0 | GT17: 0 | GU17: 0 | GV17: 1102Calamansi | GW17: 97.4 | GX17: 0 | GY17: 94.4 | HA17: 94.4 | HB17: 0 | HC17: 1102Mango, Carabao | HD17: 0 | HE17: 0 | HF17: 0 | HH17: 0 | HI17: 0 | HJ17: 1102Papaya | HK17: 80.5 | HL17: 0 | HM17: 78 | HO17: 78 | HP17: 0 | HR17: 1102Cooking oil | HS17: 0 | HT17: 0 | HU17: 0 | HW17: 0 | HX17: 0 | HY17: 1102Brown Sugar | HZ17: 72.38 | IA17: 0 | IB17: 72.38 | ID17: 71.25 | IE17: 0 | IF17: 1102Refined Sugar | IG17: 80.83 | IH17: 0 | II17: 80.83 | IK17: 80.25 | IL17: 0
A18: R1 | B18: I - Ilocos Region | C18: R1Rice, Special | D18: 52.44 | E18: 0 | F18: 51.47 | H18: 51.47 | I18: 0 | J18: R1Rice, Well Milled | K18: 40.51 | L18: 0 | M18: 40.36 | O18: 40.48 | P18: 0 | Q18: R1Rice, Regular Milled | R18: 35.42 | S18: 0 | T18: 35.67 | V18: 35.78 | W18: 0 | Y18: R1Fresh Beef, Meat with Bones | Z18: 352.38 | AA18: 0 | AB18: 354.75 | AD18: 352.25 | AE18: 0 | AF18: R1Fresh Beef, Pure Meat | AG18: 416.17 | AH18: 0 | AI18: 421.33 | AK18: 421.33 | AL18: 0 | AM18: R1Fresh Pork, Kasim | AN18: 359.38 | AO18: 0 | AP18: 349.75 | AR18: 347.25 | AS18: 0 | AT18: R1Fresh Pork, Liempo | AU18: 372.75 | AV18: 0 | AW18: 363.38 | AY18: 363.38 | AZ18: 0 | BA18: R1Fresh Pork, Meat with Bones | BB18: 323.75 | BC18: 0 | BD18: 326.88 | BF18: 324.38 | BG18: 0 | BH18: R1Dressed Chicken | BI18: 233.13 | BJ18: 0 | BK18: 242.5 | BM18: 241.25 | BN18: 0 | BO18: R1Chicken egg, med. (piece) | BP18: 8.56 | BQ18: 0 | BR18: 8.69 | BT18: 8.69 | BU18: 0 | BW18: R1Bangus | BX18: 230 | BY18: 0 | BZ18: 241.25 | CB18: 239.38 | CC18: 0 | CD18: R1Galunggong | CE18: 272.5 | CF18: 0 | CG18: 261.25 | CI18: 280 | CJ18: 0 | CK18: R1Tilapia | CL18: 157.5 | CM18: 0 | CN18: 159.38 | CP18: 153.75 | CQ18: 0 | CS18: R1Ampalaya | CT18: 117.5 | CU18: 0 | CV18: 82.75 | CX18: 86.5 | CY18: 0 | CZ18: R1Cabbage | DA18: 121.25 | DB18: 0 | DC18: 86.63 | DE18: 79.13 | DF18: 0 | DG18: R1Carrot | DH18: 228.88 | DI18: 0 | DJ18: 211.5 | DL18: 221.5 | DM18: 0 | DN18: R1Eggplant | DO18: 112.5 | DP18: 0 | DQ18: 83.63 | DS18: 76.63 | DT18: 0 | DU18: R1Baguio Beans | DV18: 195 | DW18: 0 | DX18: 165 | DZ18: 137.5 | EA18: 0 | EB18: R1Pechay, Native | EC18: 89.65 | ED18: 0 | EE18: 101.65 | EG18: 101.65 | EH18: 0 | EI18: R1String Beans | EJ18: 106.67 | EK18: 0 | EL18: 85.5 | EN18: 92.17 | EO18: 0 | EP18: R1Tomato | EQ18: 63.13 | ER18: 0 | ES18: 91.25 | EU18: 97.38 | EV18: 0 | EW18: R1White Potato | EX18: 104.5 | EY18: 0 | EZ18: 94.38 | FB18: 93.13 | FC18: 0 | FE18: R1Onion, Red | FF18: 160.83 | FG18: 0 | FH18: 161 | FJ18: 157.67 | FK18: 0 | FL18: R1Garlic, Native | FM18: 243.33 | FN18: 0 | FO18: 249.17 | FQ18: 249.17 | FR18: 0 | FS18: R1Garlic, Imported | FT18: 150 | FU18: 0 | FV18: 150 | FX18: 145 | FY18: 0 | FZ18: R1Ginger, Hawaiian | GA18: 172.5 | GB18: 0 | GC18: 149.38 | GE18: 149.38 | GF18: 0 | GH18: R1Banana, Lakatan | GI18: 86.67 | GJ18: 0 | GK18: 85.83 | GM18: 84.17 | GN18: 0 | GO18: R1Banana, Latundan | GP18: 69.17 | GQ18: 0 | GR18: 67.17 | GT18: 67.17 | GU18: 0 | GV18: R1Calamansi | GW18: 71.25 | GX18: 0 | GY18: 68.75 | HA18: 70 | HB18: 0 | HC18: R1Mango, Carabao | HD18: 165 | HE18: 0 | HF18: 170 | HH18: 160 | HI18: 0 | HJ18: R1Papaya | HK18: 72.5 | HL18: 0 | HM18: 72.38 | HO18: 62.38 | HP18: 0 | HR18: R1Cooking oil | HS18: 112.68 | HT18: 0 | HU18: 112.68 | HW18: 112.68 | HX18: 0 | HY18: R1Brown Sugar | HZ18: 77.98 | IA18: 0 | IB18: 77.51 | ID18: 77.51 | IE18: 0 | IF18: R1Refined Sugar | IG18: 84.5 | IH18: 0 | II18: 84.5 | IK18: 84.5 | IL18: 0
A19: 28 | B19: Ilocos Norte | C19: 28Rice, Special | D19: 47.25 | E19: 0 | F19: 47.25 | H19: 47.25 | I19: 0 | J19: 28Rice, Well Milled | K19: 37.54 | L19: 0 | M19: 37.71 | O19: 37.71 | P19: 0 | Q19: 28Rice, Regular Milled | R19: 34 | S19: 0 | T19: 34 | V19: 34 | W19: 0 | Y19: 28Fresh Beef, Meat with Bones | Z19: 352.5 | AA19: 0 | AB19: 352.5 | AD19: 352.5 | AE19: 0 | AF19: 28Fresh Beef, Pure Meat | AG19: 426 | AH19: 0 | AI19: 426 | AK19: 426 | AL19: 0 | AM19: 28Fresh Pork, Kasim | AN19: 350 | AO19: 0 | AP19: 350 | AR19: 350 | AS19: 0 | AT19: 28Fresh Pork, Liempo | AU19: 360 | AV19: 0 | AW19: 360 | AY19: 360 | AZ19: 0 | BA19: 28Fresh Pork, Meat with Bones | BB19: 300 | BC19: 0 | BD19: 300 | BF19: 300 | BG19: 0 | BH19: 28Dressed Chicken | BI19: 235 | BJ19: 0 | BK19: 240 | BM19: 240 | BN19: 0 | BO19: 28Chicken egg, med. (piece) | BP19: 9.25 | BQ19: 0 | BR19: 9.25 | BT19: 9.25 | BU19: 0 | BW19: 28Bangus | BX19: 225 | BY19: 0 | BZ19: 225 | CB19: 225 | CC19: 0 | CD19: 28Galunggong | CE19: 245 | CF19: 0 | CG19: 250 | CI19: 250 | CJ19: 0 | CK19: 28Tilapia | CL19: 160 | CM19: 0 | CN19: 160 | CP19: 160 | CQ19: 0 | CS19: 28Ampalaya | CT19: 0 | CU19: 0 | CV19: 0 | CX19: 0 | CY19: 0 | CZ19: 28Cabbage | DA19: 100 | DB19: 0 | DC19: 90 | DE19: 80 | DF19: 0 | DG19: 28Carrot | DH19: 190 | DI19: 0 | DJ19: 245 | DL19: 280 | DM19: 0 | DN19: 28Eggplant | DO19: 110 | DP19: 0 | DQ19: 95 | DS19: 80 | DT19: 0 | DU19: 28Baguio Beans | DV19: 0 | DW19: 0 | DX19: 0 | DZ19: 0 | EA19: 0 | EB19: 28Pechay, Native | EC19: 0 | ED19: 0 | EE19: 0 | EG19: 0 | EH19: 0 | EI19: 28String Beans | EJ19: 0 | EK19: 0 | EL19: 0 | EN19: 0 | EO19: 0 | EP19: 28Tomato | EQ19: 42.5 | ER19: 0 | ES19: 60 | EU19: 70 | EV19: 0 | EW19: 28White Potato | EX19: 100 | EY19: 0 | EZ19: 100 | FB19: 100 | FC19: 0 | FE19: 28Onion, Red | FF19: 165 | FG19: 0 | FH19: 170 | FJ19: 160 | FK19: 0 | FL19: 28Garlic, Native | FM19: 0 | FN19: 0 | FO19: 0 | FQ19: 0 | FR19: 0 | FS19: 28Garlic, Imported | FT19: 150 | FU19: 0 | FV19: 150 | FX19: 145 | FY19: 0 | FZ19: 28Ginger, Hawaiian | GA19: 160 | GB19: 0 | GC19: 155 | GE19: 155 | GF19: 0 | GH19: 28Banana, Lakatan | GI19: 100 | GJ19: 0 | GK19: 100 | GM19: 95 | GN19: 0 | GO19: 28Banana, Latundan | GP19: 62.5 | GQ19: 0 | GR19: 62.5 | GT19: 62.5 | GU19: 0 | GV19: 28Calamansi | GW19: 60 | GX19: 0 | GY19: 60 | HA19: 60 | HB19: 0 | HC19: 28Mango, Carabao | HD19: 0 | HE19: 0 | HF19: 0 | HH19: 0 | HI19: 0 | HJ19: 28Papaya | HK19: 70 | HL19: 0 | HM19: 70 | HO19: 75 | HP19: 0 | HR19: 28Cooking oil | HS19: 0 | HT19: 0 | HU19: 0 | HW19: 0 | HX19: 0 | HY19: 28Brown Sugar | HZ19: 80 | IA19: 0 | IB19: 80 | ID19: 80 | IE19: 0 | IF19: 28Refined Sugar | IG19: 90.5 | IH19: 0 | II19: 90.5 | IK19: 90.5 | IL19: 0
A20: 29 | B20: Ilocos Sur | C20: 29Rice, Special | D20: 50.5 | E20: 0 | F20: 48.25 | H20: 48.25 | I20: 0 | J20: 29Rice, Well Milled | K20: 39 | L20: 0 | M20: 38.5 | O20: 38.5 | P20: 0 | Q20: 29Rice, Regular Milled | R20: 30.5 | S20: 0 | T20: 35 | V20: 35 | W20: 0 | Y20: 29Fresh Beef, Meat with Bones | Z20: 300 | AA20: 0 | AB20: 300 | AD20: 300 | AE20: 0 | AF20: 29Fresh Beef, Pure Meat | AG20: 400 | AH20: 0 | AI20: 400 | AK20: 400 | AL20: 0 | AM20: 29Fresh Pork, Kasim | AN20: 360 | AO20: 0 | AP20: 320 | AR20: 320 | AS20: 0 | AT20: 29Fresh Pork, Liempo | AU20: 360 | AV20: 0 | AW20: 320 | AY20: 320 | AZ20: 0 | BA20: 29Fresh Pork, Meat with Bones | BB20: 295 | BC20: 0 | BD20: 300 | BF20: 300 | BG20: 0 | BH20: 29Dressed Chicken | BI20: 240 | BJ20: 0 | BK20: 270 | BM20: 270 | BN20: 0 | BO20: 29Chicken egg, med. (piece) | BP20: 8 | BQ20: 0 | BR20: 8.5 | BT20: 8.5 | BU20: 0 | BW20: 29Bangus | BX20: 280 | BY20: 0 | BZ20: 280 | CB20: 280 | CC20: 0 | CD20: 29Galunggong | CE20: 280 | CF20: 0 | CG20: 280 | CI20: 300 | CJ20: 0 | CK20: 29Tilapia | CL20: 180 | CM20: 0 | CN20: 180 | CP20: 160 | CQ20: 0 | CS20: 29Ampalaya | CT20: 120 | CU20: 0 | CV20: 80 | CX20: 70 | CY20: 0 | CZ20: 29Cabbage | DA20: 170 | DB20: 0 | DC20: 90 | DE20: 70 | DF20: 0 | DG20: 29Carrot | DH20: 450 | DI20: 0 | DJ20: 220 | DL20: 240 | DM20: 0 | DN20: 29Eggplant | DO20: 100 | DP20: 0 | DQ20: 70 | DS20: 75 | DT20: 0 | DU20: 29Baguio Beans | DV20: 250 | DW20: 0 | DX20: 205 | DZ20: 150 | EA20: 0 | EB20: 29Pechay, Native | EC20: 0 | ED20: 0 | EE20: 0 | EG20: 0 | EH20: 0 | EI20: 29String Beans | EJ20: 120 | EK20: 0 | EL20: 75 | EN20: 100 | EO20: 0 | EP20: 29Tomato | EQ20: 80 | ER20: 0 | ES20: 75 | EU20: 100 | EV20: 0 | EW20: 29White Potato | EX20: 100 | EY20: 0 | EZ20: 95 | FB20: 100 | FC20: 0 | FE20: 29Onion, Red | FF20: 160 | FG20: 0 | FH20: 150 | FJ20: 150 | FK20: 0 | FL20: 29Garlic, Native | FM20: 250 | FN20: 0 | FO20: 250 | FQ20: 250 | FR20: 0 | FS20: 29Garlic, Imported | FT20: 0 | FU20: 0 | FV20: 0 | FX20: 0 | FY20: 0 | FZ20: 29Ginger, Hawaiian | GA20: 170 | GB20: 0 | GC20: 140 | GE20: 140 | GF20: 0 | GH20: 29Banana, Lakatan | GI20: 0 | GJ20: 0 | GK20: 0 | GM20: 0 | GN20: 0 | GO20: 29Banana, Latundan | GP20: 80 | GQ20: 0 | GR20: 80 | GT20: 80 | GU20: 0 | GV20: 29Calamansi | GW20: 75 | GX20: 0 | GY20: 75 | HA20: 80 | HB20: 0 | HC20: 29Mango, Carabao | HD20: 0 | HE20: 0 | HF20: 0 | HH20: 0 | HI20: 0 | HJ20: 29Papaya | HK20: 100 | HL20: 0 | HM20: 100 | HO20: 55 | HP20: 0 | HR20: 29Cooking oil | HS20: 0 | HT20: 0 | HU20: 0 | HW20: 0 | HX20: 0 | HY20: 29Brown Sugar | HZ20: 79.93 | IA20: 0 | IB20: 78.28 | ID20: 78.28 | IE20: 0 | IF20: 29Refined Sugar | IG20: 0 | IH20: 0 | II20: 0 | IK20: 0 | IL20: 0
A21: 33 | B21: La Union | C21: 33Rice, Special | D21: 58 | E21: 0 | F21: 58 | H21: 58 | I21: 0 | J21: 33Rice, Well Milled | K21: 40 | L21: 0 | M21: 40 | O21: 40 | P21: 0 | Q21: 33Rice, Regular Milled | R21: 35.23 | S21: 0 | T21: 34.78 | V21: 35.23 | W21: 0 | Y21: 33Fresh Beef, Meat with Bones | Z21: 375 | AA21: 0 | AB21: 380 | AD21: 370 | AE21: 0 | AF21: 33Fresh Beef, Pure Meat | AG21: 0 | AH21: 0 | AI21: 0 | AK21: 0 | AL21: 0 | AM21: 33Fresh Pork, Kasim | AN21: 355 | AO21: 0 | AP21: 355 | AR21: 345 | AS21: 0 | AT21: 33Fresh Pork, Liempo | AU21: 360 | AV21: 0 | AW21: 360 | AY21: 360 | AZ21: 0 | BA21: 33Fresh Pork, Meat with Bones | BB21: 350 | BC21: 0 | BD21: 350 | BF21: 340 | BG21: 0 | BH21: 33Dressed Chicken | BI21: 250 | BJ21: 0 | BK21: 245 | BM21: 240 | BN21: 0 | BO21: 33Chicken egg, med. (piece) | BP21: 8.5 | BQ21: 0 | BR21: 8.5 | BT21: 8.5 | BU21: 0 | BW21: 33Bangus | BX21: 215 | BY21: 0 | BZ21: 210 | CB21: 210 | CC21: 0 | CD21: 33Galunggong | CE21: 270 | CF21: 0 | CG21: 220 | CI21: 240 | CJ21: 0 | CK21: 33Tilapia | CL21: 140 | CM21: 0 | CN21: 140 | CP21: 140 | CQ21: 0 | CS21: 33Ampalaya | CT21: 0 | CU21: 0 | CV21: 0 | CX21: 0 | CY21: 0 | CZ21: 33Cabbage | DA21: 105 | DB21: 0 | DC21: 80 | DE21: 80 | DF21: 0 | DG21: 33Carrot | DH21: 150 | DI21: 0 | DJ21: 165 | DL21: 150 | DM21: 0 | DN21: 33Eggplant | DO21: 160 | DP21: 0 | DQ21: 120 | DS21: 80 | DT21: 0 | DU21: 33Baguio Beans | DV21: 140 | DW21: 0 | DX21: 125 | DZ21: 125 | EA21: 0 | EB21: 33Pechay, Native | EC21: 114.29 | ED21: 0 | EE21: 114.29 | EG21: 114.29 | EH21: 0 | EI21: 33String Beans | EJ21: 90 | EK21: 0 | EL21: 90 | EN21: 90 | EO21: 0 | EP21: 33Tomato | EQ21: 80 | ER21: 0 | ES21: 100 | EU21: 100 | EV21: 0 | EW21: 33White Potato | EX21: 80 | EY21: 0 | EZ21: 90 | FB21: 90 | FC21: 0 | FE21: 33Onion, Red | FF21: 0 | FG21: 0 | FH21: 0 | FJ21: 0 | FK21: 0 | FL21: 33Garlic, Native | FM21: 250 | FN21: 0 | FO21: 250 | FQ21: 250 | FR21: 0 | FS21: 33Garlic, Imported | FT21: 0 | FU21: 0 | FV21: 0 | FX21: 0 | FY21: 0 | FZ21: 33Ginger, Hawaiian | GA21: 160 | GB21: 0 | GC21: 160 | GE21: 160 | GF21: 0 | GH21: 33Banana, Lakatan | GI21: 80 | GJ21: 0 | GK21: 80 | GM21: 80 | GN21: 0 | GO21: 33Banana, Latundan | GP21: 0 | GQ21: 0 | GR21: 0 | GT21: 0 | GU21: 0 | GV21: 33Calamansi | GW21: 80 | GX21: 0 | GY21: 80 | HA21: 80 | HB21: 0 | HC21: 33Mango, Carabao | HD21: 165 | HE21: 0 | HF21: 170 | HH21: 160 | HI21: 0 | HJ21: 33Papaya | HK21: 55 | HL21: 0 | HM21: 55 | HO21: 55 | HP21: 0 | HR21: 33Cooking oil | HS21: 0 | HT21: 0 | HU21: 0 | HW21: 0 | HX21: 0 | HY21: 33Brown Sugar | HZ21: 83 | IA21: 0 | IB21: 83 | ID21: 83 | IE21: 0 | IF21: 33Refined Sugar | IG21: 0 | IH21: 0 | II21: 0 | IK21: 0 | IL21: 0
A22: 55 | B22: Pangasinan | C22: 55Rice, Special | D22: 54 | E22: 0 | F22: 52.38 | H22: 52.38 | I22: 0 | J22: 55Rice, Well Milled | K22: 45.5 | L22: 0 | M22: 45.21 | O22: 45.71 | P22: 0 | Q22: 55Rice, Regular Milled | R22: 41.94 | S22: 0 | T22: 38.9 | V22: 38.9 | W22: 0 | Y22: 55Fresh Beef, Meat with Bones | Z22: 382 | AA22: 0 | AB22: 386.5 | AD22: 386.5 | AE22: 0 | AF22: 55Fresh Beef, Pure Meat | AG22: 422.5 | AH22: 0 | AI22: 438 | AK22: 438 | AL22: 0 | AM22: 55Fresh Pork, Kasim | AN22: 372.5 | AO22: 0 | AP22: 374 | AR22: 374 | AS22: 0 | AT22: 55Fresh Pork, Liempo | AU22: 411 | AV22: 0 | AW22: 413.5 | AY22: 413.5 | AZ22: 0 | BA22: 55Fresh Pork, Meat with Bones | BB22: 350 | BC22: 0 | BD22: 357.5 | BF22: 357.5 | BG22: 0 | BH22: 55Dressed Chicken | BI22: 207.5 | BJ22: 0 | BK22: 215 | BM22: 215 | BN22: 0 | BO22: 55Chicken egg, med. (piece) | BP22: 8.5 | BQ22: 0 | BR22: 8.5 | BT22: 8.5 | BU22: 0 | BW22: 55Bangus | BX22: 200 | BY22: 0 | BZ22: 250 | CB22: 242.5 | CC22: 0 | CD22: 55Galunggong | CE22: 295 | CF22: 0 | CG22: 295 | CI22: 330 | CJ22: 0 | CK22: 55Tilapia | CL22: 150 | CM22: 0 | CN22: 157.5 | CP22: 155 | CQ22: 0 | CS22: 55Ampalaya | CT22: 115 | CU22: 0 | CV22: 85.5 | CX22: 103 | CY22: 0 | CZ22: 55Cabbage | DA22: 110 | DB22: 0 | DC22: 86.5 | DE22: 86.5 | DF22: 0 | DG22: 55Carrot | DH22: 125.5 | DI22: 0 | DJ22: 216 | DL22: 216 | DM22: 0 | DN22: 55Eggplant | DO22: 80 | DP22: 0 | DQ22: 49.5 | DS22: 71.5 | DT22: 0 | DU22: 55Baguio Beans | DV22: 0 | DW22: 0 | DX22: 0 | DZ22: 0 | EA22: 0 | EB22: 55Pechay, Native | EC22: 65 | ED22: 0 | EE22: 89 | EG22: 89 | EH22: 0 | EI22: 55String Beans | EJ22: 110 | EK22: 0 | EL22: 91.5 | EN22: 86.5 | EO22: 0 | EP22: 55Tomato | EQ22: 50 | ER22: 0 | ES22: 130 | EU22: 119.5 | EV22: 0 | EW22: 55White Potato | EX22: 138 | EY22: 0 | EZ22: 92.5 | FB22: 82.5 | FC22: 0 | FE22: 55Onion, Red | FF22: 157.5 | FG22: 0 | FH22: 163 | FJ22: 163 | FK22: 0 | FL22: 55Garlic, Native | FM22: 230 | FN22: 0 | FO22: 247.5 | FQ22: 247.5 | FR22: 0 | FS22: 55Garlic, Imported | FT22: 0 | FU22: 0 | FV22: 0 | FX22: 0 | FY22: 0 | FZ22: 55Ginger, Hawaiian | GA22: 200 | GB22: 0 | GC22: 142.5 | GE22: 142.5 | GF22: 0 | GH22: 55Banana, Lakatan | GI22: 80 | GJ22: 0 | GK22: 77.5 | GM22: 77.5 | GN22: 0 | GO22: 55Banana, Latundan | GP22: 65 | GQ22: 0 | GR22: 59 | GT22: 59 | GU22: 0 | GV22: 55Calamansi | GW22: 70 | GX22: 0 | GY22: 60 | HA22: 60 | HB22: 0 | HC22: 55Mango, Carabao | HD22: 0 | HE22: 0 | HF22: 0 | HH22: 0 | HI22: 0 | HJ22: 55Papaya | HK22: 65 | HL22: 0 | HM22: 64.5 | HO22: 64.5 | HP22: 0 | HR22: 55Cooking oil | HS22: 112.68 | HT22: 0 | HU22: 112.68 | HW22: 112.68 | HX22: 0 | HY22: 55Brown Sugar | HZ22: 69 | IA22: 0 | IB22: 68.75 | ID22: 68.75 | IE22: 0 | IF22: 55Refined Sugar | IG22: 78.5 | IH22: 0 | II22: 78.5 | IK22: 78.5 | IL22: 0
A23: R2 | B23: II - Cagayan Valley | C23: R2Rice, Special | D23: 52.32 | E23: 0 | F23: 52.79 | H23: 52.79 | I23: 0 | J23: R2Rice, Well Milled | K23: 40.49 | L23: 0 | M23: 39.24 | O23: 39.13 | P23: 0 | Q23: R2Rice, Regular Milled | R23: 31.06 | S23: 0 | T23: 32.22 | V23: 31.91 | W23: 0 | Y23: R2Fresh Beef, Meat with Bones | Z23: 354.5 | AA23: 0 | AB23: 353.5 | AD23: 353.5 | AE23: 0 | AF23: R2Fresh Beef, Pure Meat | AG23: 425 | AH23: 0 | AI23: 430 | AK23: 430 | AL23: 0 | AM23: R2Fresh Pork, Kasim | AN23: 383 | AO23: 0 | AP23: 382 | AR23: 382 | AS23: 0 | AT23: R2Fresh Pork, Liempo | AU23: 385 | AV23: 0 | AW23: 383 | AY23: 383 | AZ23: 0 | BA23: R2Fresh Pork, Meat with Bones | BB23: 370 | BC23: 0 | BD23: 369 | BF23: 369 | BG23: 0 | BH23: R2Dressed Chicken | BI23: 232.5 | BJ23: 0 | BK23: 233.5 | BM23: 233.5 | BN23: 0 | BO23: R2Chicken egg, med. (piece) | BP23: 10.23 | BQ23: 0 | BR23: 10.3 | BT23: 10.3 | BU23: 0 | BW23: R2Bangus | BX23: 268 | BY23: 0 | BZ23: 271.5 | CB23: 271.5 | CC23: 0 | CD23: R2Galunggong | CE23: 270 | CF23: 0 | CG23: 265 | CI23: 265 | CJ23: 0 | CK23: R2Tilapia | CL23: 171.25 | CM23: 0 | CN23: 171.25 | CP23: 171.25 | CQ23: 0 | CS23: R2Ampalaya | CT23: 136.25 | CU23: 0 | CV23: 116.25 | CX23: 116.25 | CY23: 0 | CZ23: R2Cabbage | DA23: 138.5 | DB23: 0 | DC23: 119.5 | DE23: 119.5 | DF23: 0 | DG23: R2Carrot | DH23: 178.75 | DI23: 0 | DJ23: 185 | DL23: 185 | DM23: 0 | DN23: R2Eggplant | DO23: 114 | DP23: 0 | DQ23: 79.5 | DS23: 79.5 | DT23: 0 | DU23: R2Baguio Beans | DV23: 115 | DW23: 0 | DX23: 110 | DZ23: 110 | EA23: 0 | EB23: R2Pechay, Native | EC23: 93.75 | ED23: 0 | EE23: 93.75 | EG23: 93.75 | EH23: 0 | EI23: R2String Beans | EJ23: 104.06 | EK23: 0 | EL23: 96.25 | EN23: 96.25 | EO23: 0 | EP23: R2Tomato | EQ23: 81.25 | ER23: 0 | ES23: 100 | EU23: 100 | EV23: 0 | EW23: R2White Potato | EX23: 111 | EY23: 0 | EZ23: 112.5 | FB23: 112.5 | FC23: 0 | FE23: R2Onion, Red | FF23: 173.5 | FG23: 0 | FH23: 177.5 | FJ23: 177.5 | FK23: 0 | FL23: R2Garlic, Native | FM23: 172.5 | FN23: 0 | FO23: 172.5 | FQ23: 172.5 | FR23: 0 | FS23: R2Garlic, Imported | FT23: 157.5 | FU23: 0 | FV23: 157.5 | FX23: 157.5 | FY23: 0 | FZ23: R2Ginger, Hawaiian | GA23: 188 | GB23: 0 | GC23: 187 | GE23: 187 | GF23: 0 | GH23: R2Banana, Lakatan | GI23: 81.25 | GJ23: 0 | GK23: 74.38 | GM23: 74.38 | GN23: 0 | GO23: R2Banana, Latundan | GP23: 72.5 | GQ23: 0 | GR23: 51.25 | GT23: 51.25 | GU23: 0 | GV23: R2Calamansi | GW23: 123.75 | GX23: 0 | GY23: 115 | HA23: 115 | HB23: 0 | HC23: R2Mango, Carabao | HD23: 132.5 | HE23: 0 | HF23: 160 | HH23: 160 | HI23: 0 | HJ23: R2Papaya | HK23: 50 | HL23: 0 | HM23: 48.33 | HO23: 48.33 | HP23: 0 | HR23: R2Cooking oil | HS23: 178.15 | HT23: 0 | HU23: 178.15 | HW23: 178.15 | HX23: 0 | HY23: R2Brown Sugar | HZ23: 77.65 | IA23: 0 | IB23: 77.65 | ID23: 77.65 | IE23: 0 | IF23: R2Refined Sugar | IG23: 85 | IH23: 0 | II23: 84.63 | IK23: 84.63 | IL23: 0
A24: 9 | B24: Batanes | C24: 9Rice, Special | D24: 71 | E24: 0 | F24: 71 | H24: 71 | I24: 0 | J24: 9Rice, Well Milled | K24: 56.84 | L24: 0 | M24: 54 | O24: 54 | P24: 0 | Q24: 9Rice, Regular Milled | R24: 0 | S24: 0 | T24: 0 | V24: 0 | W24: 0 | Y24: 9Fresh Beef, Meat with Bones | Z24: 280 | AA24: 0 | AB24: 280 | AD24: 280 | AE24: 0 | AF24: 9Fresh Beef, Pure Meat | AG24: 0 | AH24: 0 | AI24: 0 | AK24: 0 | AL24: 0 | AM24: 9Fresh Pork, Kasim | AN24: 400 | AO24: 0 | AP24: 400 | AR24: 400 | AS24: 0 | AT24: 9Fresh Pork, Liempo | AU24: 400 | AV24: 0 | AW24: 400 | AY24: 400 | AZ24: 0 | BA24: 9Fresh Pork, Meat with Bones | BB24: 400 | BC24: 0 | BD24: 400 | BF24: 400 | BG24: 0 | BH24: 9Dressed Chicken | BI24: 270 | BJ24: 0 | BK24: 270 | BM24: 270 | BN24: 0 | BO24: 9Chicken egg, med. (piece) | BP24: 13 | BQ24: 0 | BR24: 13 | BT24: 13 | BU24: 0 | BW24: 9Bangus | BX24: 305 | BY24: 0 | BZ24: 305 | CB24: 305 | CC24: 0 | CD24: 9Galunggong | CE24: 225 | CF24: 0 | CG24: 200 | CI24: 200 | CJ24: 0 | CK24: 9Tilapia | CL24: 0 | CM24: 0 | CN24: 0 | CP24: 0 | CQ24: 0 | CS24: 9Ampalaya | CT24: 175 | CU24: 0 | CV24: 200 | CX24: 200 | CY24: 0 | CZ24: 9Cabbage | DA24: 170 | DB24: 0 | DC24: 180 | DE24: 180 | DF24: 0 | DG24: 9Carrot | DH24: 0 | DI24: 0 | DJ24: 0 | DL24: 0 | DM24: 0 | DN24: 9Eggplant | DO24: 175 | DP24: 0 | DQ24: 150 | DS24: 150 | DT24: 0 | DU24: 9Baguio Beans | DV24: 0 | DW24: 0 | DX24: 0 | DZ24: 0 | EA24: 0 | EB24: 9Pechay, Native | EC24: 110 | ED24: 0 | EE24: 110 | EG24: 110 | EH24: 0 | EI24: 9String Beans | EJ24: 175 | EK24: 0 | EL24: 165 | EN24: 165 | EO24: 0 | EP24: 9Tomato | EQ24: 140 | ER24: 0 | ES24: 140 | EU24: 140 | EV24: 0 | EW24: 9White Potato | EX24: 190 | EY24: 0 | EZ24: 190 | FB24: 190 | FC24: 0 | FE24: 9Onion, Red | FF24: 225 | FG24: 0 | FH24: 225 | FJ24: 225 | FK24: 0 | FL24: 9Garlic, Native | FM24: 0 | FN24: 0 | FO24: 0 | FQ24: 0 | FR24: 0 | FS24: 9Garlic, Imported | FT24: 0 | FU24: 0 | FV24: 0 | FX24: 0 | FY24: 0 | FZ24: 9Ginger, Hawaiian | GA24: 280 | GB24: 0 | GC24: 280 | GE24: 280 | GF24: 0 | GH24: 9Banana, Lakatan | GI24: 0 | GJ24: 0 | GK24: 0 | GM24: 0 | GN24: 0 | GO24: 9Banana, Latundan | GP24: 85 | GQ24: 0 | GR24: 50 | GT24: 50 | GU24: 0 | GV24: 9Calamansi | GW24: 205 | GX24: 0 | GY24: 205 | HA24: 205 | HB24: 0 | HC24: 9Mango, Carabao | HD24: 195 | HE24: 0 | HF24: 210 | HH24: 210 | HI24: 0 | HJ24: 9Papaya | HK24: 0 | HL24: 0 | HM24: 0 | HO24: 0 | HP24: 0 | HR24: 9Cooking oil | HS24: 0 | HT24: 0 | HU24: 0 | HW24: 0 | HX24: 0 | HY24: 9Brown Sugar | HZ24: 95 | IA24: 0 | IB24: 95 | ID24: 95 | IE24: 0 | IF24: 9Refined Sugar | IG24: 90 | IH24: 0 | II24: 90 | IK24: 90 | IL24: 0
A25: 15 | B25: Cagayan | C25: 15Rice, Special | D25: 46.8 | E25: 0 | F25: 46.67 | H25: 46.67 | I25: 0 | J25: 15Rice, Well Milled | K25: 36.9 | L25: 0 | M25: 37.07 | O25: 37.07 | P25: 0 | Q25: 15Rice, Regular Milled | R25: 30.59 | S25: 0 | T25: 30.59 | V25: 30.59 | W25: 0 | Y25: 15Fresh Beef, Meat with Bones | Z25: 360 | AA25: 0 | AB25: 360 | AD25: 360 | AE25: 0 | AF25: 15Fresh Beef, Pure Meat | AG25: 450 | AH25: 0 | AI25: 450 | AK25: 450 | AL25: 0 | AM25: 15Fresh Pork, Kasim | AN25: 350 | AO25: 0 | AP25: 360 | AR25: 360 | AS25: 0 | AT25: 15Fresh Pork, Liempo | AU25: 370 | AV25: 0 | AW25: 370 | AY25: 370 | AZ25: 0 | BA25: 15Fresh Pork, Meat with Bones | BB25: 340 | BC25: 0 | BD25: 345 | BF25: 345 | BG25: 0 | BH25: 15Dressed Chicken | BI25: 205 | BJ25: 0 | BK25: 210 | BM25: 210 | BN25: 0 | BO25: 15Chicken egg, med. (piece) | BP25: 10 | BQ25: 0 | BR25: 10 | BT25: 10 | BU25: 0 | BW25: 15Bangus | BX25: 220 | BY25: 0 | BZ25: 230 | CB25: 230 | CC25: 0 | CD25: 15Galunggong | CE25: 320 | CF25: 0 | CG25: 320 | CI25: 320 | CJ25: 0 | CK25: 15Tilapia | CL25: 155 | CM25: 0 | CN25: 160 | CP25: 160 | CQ25: 0 | CS25: 15Ampalaya | CT25: 130 | CU25: 0 | CV25: 65 | CX25: 65 | CY25: 0 | CZ25: 15Cabbage | DA25: 105 | DB25: 0 | DC25: 55 | DE25: 55 | DF25: 0 | DG25: 15Carrot | DH25: 155 | DI25: 0 | DJ25: 155 | DL25: 155 | DM25: 0 | DN25: 15Eggplant | DO25: 95 | DP25: 0 | DQ25: 30 | DS25: 30 | DT25: 0 | DU25: 15Baguio Beans | DV25: 0 | DW25: 0 | DX25: 0 | DZ25: 0 | EA25: 0 | EB25: 15Pechay, Native | EC25: 0 | ED25: 0 | EE25: 0 | EG25: 0 | EH25: 0 | EI25: 15String Beans | EJ25: 63.75 | EK25: 0 | EL25: 52.5 | EN25: 52.5 | EO25: 0 | EP25: 15Tomato | EQ25: 40 | ER25: 0 | ES25: 65 | EU25: 65 | EV25: 0 | EW25: 15White Potato | EX25: 70 | EY25: 0 | EZ25: 67.5 | FB25: 67.5 | FC25: 0 | FE25: 15Onion, Red | FF25: 140 | FG25: 0 | FH25: 135 | FJ25: 135 | FK25: 0 | FL25: 15Garlic, Native | FM25: 165 | FN25: 0 | FO25: 165 | FQ25: 165 | FR25: 0 | FS25: 15Garlic, Imported | FT25: 0 | FU25: 0 | FV25: 0 | FX25: 0 | FY25: 0 | FZ25: 15Ginger, Hawaiian | GA25: 135 | GB25: 0 | GC25: 130 | GE25: 130 | GF25: 0 | GH25: 15Banana, Lakatan | GI25: 85 | GJ25: 0 | GK25: 67.5 | GM25: 67.5 | GN25: 0 | GO25: 15Banana, Latundan | GP25: 60 | GQ25: 0 | GR25: 52.5 | GT25: 52.5 | GU25: 0 | GV25: 15Calamansi | GW25: 0 | GX25: 0 | GY25: 0 | HA25: 0 | HB25: 0 | HC25: 15Mango, Carabao | HD25: 0 | HE25: 0 | HF25: 0 | HH25: 0 | HI25: 0 | HJ25: 15Papaya | HK25: 0 | HL25: 0 | HM25: 0 | HO25: 0 | HP25: 0 | HR25: 15Cooking oil | HS25: 146.29 | HT25: 0 | HU25: 146.29 | HW25: 146.29 | HX25: 0 | HY25: 15Brown Sugar | HZ25: 79.76 | IA25: 0 | IB25: 79.76 | ID25: 79.76 | IE25: 0 | IF25: 15Refined Sugar | IG25: 93.5 | IH25: 0 | II25: 92 | IK25: 92 | IL25: 0
