Workbook
Name \a: #REF!
Name \a: #REF!
Name \a: #REF!
Name \a: #REF!
Name \a: #REF!
Name \a: #REF!
Name \a: #REF!
Name \a: #REF!
Name \a: #REF!
Name \z: #REF!
Name \z: #REF!
Name \z: #REF!
Name \z: #REF!
Name \z: #REF!
Name \z: #REF!
Name \z: #REF!
Name \z: #REF!
Name \z: #REF!
Name _4_93: '[1]NCR-03'!#REF!
Name _4_93: '[1]NCR-03'!#REF!
Name _4_93: '[1]NCR-03'!#REF!
Name _4_93: '[1]NCR-03'!#REF!
Name _4_93: '[1]NCR-03'!#REF!
Name _4_93: '[1]NCR-03'!#REF!
Name _4_93: '[1]NCR-03'!#REF!
Name _4_93: '[1]NCR-03'!#REF!
Name _4_93: '[1]NCR-03'!#REF!
Name _84AOMM: #N/A
Name _93: #REF!
Name _93: #REF!
Name _93: #REF!
Name _93: #REF!
Name _93: #REF!
Name _93: #REF!
Name _93: #REF!
Name _93: #REF!
Name _93: #REF!
Name _R1: #REF!
Name _R1: #REF!
Name _R10: #REF!
Name _R10: #REF!
Name _R11: #REF!
Name _R11: #REF!
Name _R12: #REF!
Name _R2: #REF!
Name _R3: #REF!
Name _R4: #REF!
Name _R5: #REF!
Name _R6: #REF!
Name _R7: #REF!
Name _R8: #REF!
Name _r82001: #REF!
Name _R9: #REF!
Name _REG1: #N/A
Name _REG4: '[1]NCR-03'!#REF!
Name _REG4: '[1]NCR-03'!#REF!
Name A: #N/A
Name AOMM: #REF!
Name AOMM_93: #REF!
Name ARMM: #REF!

Sheet Table_All_SR (From Editing)
B1: Previous Month: | D1: January 2024
B2: Current Month: | D2: February 2024
B3: Current Phase: | D3: Second Phase
F4: Rice, Special | M4: Rice, Well Milled | T4: Rice, Regular Milled | AB4: Fresh Beef, Meat with Bones | AI4: Fresh Beef, Pure Meat | AP4: Fresh Pork, Kasim | AW4: Fresh Pork, Liempo | BD4: Fresh Pork, Meat with Bones | BK4: Dressed Chicken | BR4: Chicken egg, med. (piece) | BZ4: Bangus | CG4: Galunggong | CN4: Tilapia | CV4: Ampalaya | DC4: Cabbage | DJ4: Carrot | DQ4: Eggplant | DX4: Baguio Beans | EE4: Pechay, Native | EL4: String Beans | ES4: Tomato | EZ4: White Potato | FH4: Onion, Red | FO4: Garlic, Native | FV4: Garlic, Imported | GC4: Ginger, Hawaiian | GK4: Banana, Lakatan | GR4: Banana, Latundan | GY4: Calamansi | HF4: Mango, Carabao | HM4: Papaya | HU4: Cooking oil | IB4: Brown Sugar | II4: Refined Sugar
B5: Region / Province | C5: RICE, SPECIAL | J5: RICE, WELL MILLED | Q5: RICE, REGULAR MILLED | Z5: BEEF,WITH BONES | AG5: BEEF, PURE MEAT | AN5: PORK, KASIM | AU5: PORK, LIEMPO | BB5: PORK, WITH BONES | BI5: DRESSED CHICKEN | BP5: CHICKEN EGG, MED. (per piece) | BX5: BANGUS | CE5: GALUNGGONG | CL5: TILAPIA | CT5: AMPALAYA | DA5: CABBAGE | DH5: CARROT | DO5: EGGPLANT | DV5: BAGUIO BEANS | EC5: PECHAY, NATIVE | EJ5: STRING BEANS | EQ5: TOMATO | EX5: WHITE POTATO | FF5: ONION, RED | FM5: GARLIC, NATIVE | FT5: GARLIC, IMPORTED | GA5: GINGER, HAWAIIAN | GI5: BANANA, LAKATAN | GP5: BANANA, LATUNDAN | GW5: CALAMANSI | HD5: MANGO, CARABAO | HK5: PAPAYA | HS5: COOKING OIL (in PhP) | HZ5: BROWN SUGAR (in PhP per Kilogram) | IG5: REFINED SUGAR (in PhP per Kilogram)
C6: Concatenate | D6: 2nd Phase Previous Month | F6: 1st Phase Current Month | H6: 2nd Phase Current Month | J6: Concatenate | K6: 2nd Phase Previous Month | M6: 1st Phase Current Month | O6: 2nd Phase Current Month | Q6: Concatenate | R6: 2nd Phase Previous Month | T6: 1st Phase Current Month | V6: 2nd Phase Current Month | Y6: Concatenate | Z6: 2nd Phase Previous Month | AB6: 1st Phase Current Month | AD6: 2nd Phase Current Month | AF6: Concatenate | AG6: 2nd Phase Previous Month | AI6: 1st Phase Current Month | AK6: 2nd Phase Current Month | AM6: Concatenate | AN6: 2nd Phase Previous Month | AP6: 1st Phase Current Month | AR6: 2nd Phase Current Month | AT6: Concatenate | AU6: 2nd Phase Previous Month | AW6: 1st Phase Current Month | AY6: 2nd Phase Current Month | BA6: Concatenate | BB6: 2nd Phase Previous Month | BD6: 1st Phase Current Month | BF6: 2nd Phase Current Month | BH6: Concatenate | BI6: 2nd Phase Previous Month | BK6: 1st Phase Current Month | BM6: 2nd Phase Current Month | BO6: Concatenate | BP6: 2nd Phase Previous Month | BR6: 1st Phase Current Month | BT6: 2nd Phase Current Month | BW6: Concatenate | BX6: 2nd Phase Previous Month | BZ6: 1st Phase Current Month | CB6: 2nd Phase Current Month | CD6: Concatenate | CE6: 2nd Phase Previous Month | CG6: 1st Phase Current Month | CI6: 2nd Phase Current Month | CK6: Concatenate | CL6: 2nd Phase Previous Month | CN6: 1st Phase Current Month | CP6: 2nd Phase Current Month | CS6: Concatenate | CT6: 2nd Phase Previous Month | CV6: 1st Phase Current Month | CX6: 2nd Phase Current Month | CZ6: Concatenate | DA6: 2nd Phase Previous Month | DC6: 1st Phase Current Month | DE6: 2nd Phase Current Month | DG6: Concatenate | DH6: 2nd Phase Previous Month | DJ6: 1st Phase Current Month | DL6: 2nd Phase Current Month | DN6: Concatenate | DO6: 2nd Phase Previous Month | DQ6: 1st Phase Current Month | DS6: 2nd Phase Current Month | DU6: Concatenate | DV6: 2nd Phase Previous Month | DX6: 1st Phase Current Month | DZ6: 2nd Phase Current Month | EB6: Concatenate | EC6: 2nd Phase Previous Month | EE6: 1st Phase Current Month | EG6: 2nd Phase Current Month | EI6: Concatenate | EJ6: 2nd Phase Previous Month | EL6: 1st Phase Current Month | EN6: 2nd Phase Current Month | EP6: Concatenate | EQ6: 2nd Phase Previous Month | ES6: 1st Phase Current Month | EU6: 2nd Phase Current Month | EW6: Concatenate | EX6: 2nd Phase Previous Month | EZ6: 1st Phase Current Month | FB6: 2nd Phase Current Month | FE6: Concatenate | FF6: 2nd Phase Previous Month | FH6: 1st Phase Current Month | FJ6: 2nd Phase Current Month | FL6: Concatenate | FM6: 2nd Phase Previous Month | FO6: 1st Phase Current Month | FQ6: 2nd Phase Current Month | FS6: Concatenate | FT6: 2nd Phase Previous Month | FV6: 1st Phase Current Month | FX6: 2nd Phase Current Month | FZ6: Concatenate | GA6: 2nd Phase Previous Month | GC6: 1st Phase Current Month | GE6: 2nd Phase Current Month | GH6: Concatenate | GI6: 2nd Phase Previous Month | GK6: 1st Phase Current Month | GM6: 2nd Phase Current Month | GO6: Concatenate | GP6: 2nd Phase Previous Month | GR6: 1st Phase Current Month | GT6: 2nd Phase Current Month | GV6: Concatenate | GW6: 2nd Phase Previous Month | GY6: 1st Phase Current Month | HA6: 2nd Phase Current Month | HC6: Concatenate | HD6: 2nd Phase Previous Month | HF6: 1st Phase Current Month | HH6: 2nd Phase Current Month | HJ6: Concatenate | HK6: 2nd Phase Previous Month | HM6: 1st Phase Current Month | HO6: 2nd Phase Current Month | HR6: Concatenate | HS6: 2nd Phase Previous Month | HU6: 1st Phase Current Month | HW6: 2nd Phase Current Month | HY6: Concatenate | HZ6: 2nd Phase Previous Month | IB6: 1st Phase Current Month | ID6: 2nd Phase Current Month | IF6: Concatenate | IG6: 2nd Phase Previous Month | II6: 1st Phase Current Month | IK6: 2nd Phase Current Month
D7: -1 | F7: -2 | H7: -3 | K7: -4 | M7: -5 | O7: -6 | R7: -7 | T7: -8 | V7: -9 | Z7: -1 | AB7: -2 | AD7: -3 | AG7: -4 | AI7: -5 | AK7: -6 | AN7: -7 | AP7: -8 | AR7: -9 | AU7: -10 | AW7: -11 | AY7: -12 | BB7: -13 | BD7: -14 | BF7: -15 | BI7: -16 | BK7: -17 | BM7: -18 | BP7: -19 | BR7: -20 | BT7: -21 | BX7: -1 | BZ7: -2 | CB7: -3 | CE7: -4 | CG7: -5 | CI7: -6 | CL7: -7 | CN7: -8 | CP7: -9 | CT7: -1 | CV7: -2 | CX7: -3 | DA7: -4 | DC7: -5 | DE7: -6 | DH7: -7 | DJ7: -8 | DL7: -9 | DO7: -10 | DQ7: -11 | DS7: -12 | DV7: -13 | DX7: -14 | DZ7: -15 | EC7: -16 | EE7: -17 | EG7: -18 | EJ7: -19 | EL7: -20 | EN7: -21 | EQ7: -22 | ES7: -23 | EU7: -24 | EX7: -25 | EZ7: -26 | FB7: -27 | FF7: -1 | FH7: -2 | FJ7: -3 | FM7: -4 | FO7: -5 | FQ7: -6 | FT7: -7 | FV7: -8 | FX7: -9 | GA7: -10 | GC7: -11 | GE7: -12 | GI7: -1 | GK7: -2 | GM7: -3 | GP7: -4 | GR7: -5 | GT7: -6 | GW7: -7 | GY7: -8 | HA7: -9 | HD7: -10 | HF7: -11 | HH7: -12 | HK7: -13 | HM7: -14 | HO7: -15 | HS7: -1 | HU7: -2 | HW7: -3 | HZ7: -4 | IB7: -5 | ID7: -6 | IG7: -7 | II7: -8 | IK7: -9
A8: PHILIPPINES | B8: Philippines | C8: PHILIPPINESRice, Special | D8: 64.58 | E8: 0 | F8: 64.83 | H8: 64.75 | I8: 0 | J8: PHILIPPINESRice, Well Milled | K8: 56.29 | L8: 0 | M8: 56.9 | O8: 56.95 | P8: 0 | Q8: PHILIPPINESRice, Regular Milled | R8: 50.63 | S8: 0 | T8: 51.14 | V8: 51.21 | W8: 0 | Y8: PHILIPPINESFresh Beef, Meat with Bones | Z8: 341.56 | AA8: 0 | AB8: 343.74 | AD8: 344.22 | AE8: 0 | AF8: PHILIPPINESFresh Beef, Pure Meat | AG8: 421.1 | AH8: 0 | AI8: 421.82 | AK8: 420.33 | AL8: 0 | AM8: PHILIPPINESFresh Pork, Kasim | AN8: 326.94 | AO8: 0 | AP8: 331.8 | AR8: 333.64 | AS8: 0 | AT8: PHILIPPINESFresh Pork, Liempo | AU8: 346.61 | AV8: 0 | AW8: 352.41 | AY8: 354.49 | AZ8: 0 | BA8: PHILIPPINESFresh Pork, Meat with Bones | BB8: 295.95 | BC8: 0 | BD8: 299.94 | BE8: r | BF8: 302.03 | BG8: 0 | BH8: PHILIPPINESDressed Chicken | BI8: 192 | BJ8: 0 | BK8: 191.12 | BM8: 191.44 | BN8: 0 | BO8: PHILIPPINESChicken egg, med. (piece) | BP8: 8.87 | BQ8: 0 | BR8: 8.73 | BT8: 8.72 | BU8: 0 | BW8: PHILIPPINESBangus | BX8: 213.17 | BY8: 0 | BZ8: 212.17 | CB8: 212.32 | CC8: 0 | CD8: PHILIPPINESGalunggong | CE8: 213.92 | CF8: 0 | CG8: 213.7 | CH8: r | CI8: 207.45 | CJ8: 0 | CK8: PHILIPPINESTilapia | CL8: 167.7 | CM8: 0 | CN8: 167.51 | CO8: r | CP8: 168.11 | CQ8: 0 | CS8: PHILIPPINESAmpalaya | CT8: 105.52 | CU8: 0 | CV8: 106.02 | CX8: 105.46 | CY8: 0 | CZ8: PHILIPPINESCabbage | DA8: 74.97 | DB8: 0 | DC8: 74.77 | DE8: 76.22 | DF8: 0 | DG8: PHILIPPINESCarrot | DH8: 117.69 | DI8: 0 | DJ8: 120.78 | DL8: 118.37 | DM8: 0 | DN8: PHILIPPINESEggplant | DO8: 86.15 | DP8: 0 | DQ8: 83.41 | DS8: 81.95 | DT8: 0 | DU8: PHILIPPINESBaguio Beans | DV8: 111.5 | DW8: 0 | DX8: 110.06 | DY8: r | DZ8: 110.23 | EA8: 0 | EB8: PHILIPPINESPechay, Native | EC8: 98.49 | ED8: 0 | EE8: 90.81 | EG8: 89.88 | EH8: 0 | EI8: PHILIPPINESString Beans | EJ8: 100.26 | EK8: 0 | EL8: 100 | EN8: 99.38 | EO8: 0 | EP8: PHILIPPINESTomato | EQ8: 98.37 | ER8: 0 | ES8: 88.55 | EU8: 80.09 | EV8: 0 | EW8: PHILIPPINESWhite Potato | EX8: 147.16 | EY8: 0 | EZ8: 147.42 | FB8: 145.07 | FC8: 0 | FE8: PHILIPPINESOnion, Red | FF8: 162.62 | FG8: 0 | FH8: 144.32 | FJ8: 134.98 | FK8: 0 | FL8: PHILIPPINESGarlic, Native | FM8: 170.73 | FN8: 0 | FO8: 171 | FQ8: 169.28 | FR8: 0 | FS8: PHILIPPINESGarlic, Imported | FT8: 161.27 | FU8: 0 | FV8: 162.28 | FX8: 161.83 | FY8: 0 | FZ8: PHILIPPINESGinger, Hawaiian | GA8: 117.8 | GB8: 0 | GC8: 119.31 | GE8: 121.62 | GF8: 0 | GH8: PHILIPPINESBanana, Lakatan | GI8: 87.61 | GJ8: 0 | GK8: 88.34 | GM8: 88.78 | GN8: 0 | GO8: PHILIPPINESBanana, Latundan | GP8: 49.83 | GQ8: 0 | GR8: 50.89 | GT8: 50.79 | GU8: 0 | GV8: PHILIPPINESCalamansi | GW8: 84.62 | GX8: 0 | GY8: 82.42 | HA8: 81.77 | HB8: 0 | HC8: PHILIPPINESMango, Carabao | HD8: 170.58 | HE8: 0 | HF8: 168.13 | HH8: 166.03 | HI8: 0 | HJ8: PHILIPPINESPapaya | HK8: 50.36 | HL8: 0 | HM8: 50.74 | HO8: 50.38 | HP8: 0 | HR8: PHILIPPINESCooking oil | HS8: 156.04 | HT8: 0 | HU8: 154.96 | HV8: r | HW8: 155.15 | HX8: 0 | HY8: PHILIPPINESBrown Sugar | HZ8: 76.47 | IA8: 0 | IB8: 75.82 | IC8: r | ID8: 75.89 | IE8: 0 | IF8: PHILIPPINESRefined Sugar | IG8: 87.31 | IH8: 0 | II8: 86.9 | IK8: 86.99 | IL8: 0
A9: NCR | B9: NCR- National Capital Region | C9: NCRRice, Special | D9: 60.95 | E9: 0 | F9: 61.03 | H9: 60.99 | I9: 0 | J9: NCRRice, Well Milled | K9: 52.36 | L9: 0 | M9: 52.63 | O9: 52.63 | P9: 0 | Q9: NCRRice, Regular Milled | R9: 44.13 | S9: 0 | T9: 44.23 | V9: 44.55 | W9: 0 | Y9: NCRFresh Beef, Meat with Bones | Z9: 400.32 | AA9: 0 | AB9: 399.07 | AD9: 398.01 | AE9: 0 | AF9: NCRFresh Beef, Pure Meat | AG9: 452.71 | AH9: 0 | AI9: 452.88 | AK9: 453.14 | AL9: 0 | AM9: NCRFresh Pork, Kasim | AN9: 326.33 | AO9: 0 | AP9: 335.71 | AR9: 336.73 | AS9: 0 | AT9: NCRFresh Pork, Liempo | AU9: 370.45 | AV9: 0 | AW9: 377.26 | AY9: 378.38 | AZ9: 0 | BA9: NCRFresh Pork, Meat with Bones | BB9: 304.64 | BC9: 0 | BD9: 309.62 | BF9: 310.06 | BG9: 0 | BH9: NCRDressed Chicken | BI9: 182.65 | BJ9: 0 | BK9: 183.37 | BM9: 183.02 | BN9: 0 | BO9: NCRChicken egg, med. (piece) | BP9: 8.06 | BQ9: 0 | BR9: 7.93 | BT9: 7.88 | BU9: 0 | BW9: NCRBangus | BX9: 216.29 | BY9: 0 | BZ9: 214.82 | CB9: 213.77 | CC9: 0 | CD9: NCRGalunggong | CE9: 266.56 | CF9: 0 | CG9: 258.9 | CI9: 251.74 | CJ9: 0 | CK9: NCRTilapia | CL9: 146.58 | CM9: 0 | CN9: 144.93 | CP9: 144.15 | CQ9: 0 | CS9: NCRAmpalaya | CT9: 112.79 | CU9: 0 | CV9: 123.21 | CX9: 124.96 | CY9: 0 | CZ9: NCRCabbage | DA9: 63.8 | DB9: 0 | DC9: 67.93 | DE9: 66.67 | DF9: 0 | DG9: NCRCarrot | DH9: 99.41 | DI9: 0 | DJ9: 121.83 | DL9: 118.61 | DM9: 0 | DN9: NCREggplant | DO9: 86.55 | DP9: 0 | DQ9: 82.73 | DS9: 85.52 | DT9: 0 | DU9: NCRBaguio Beans | DV9: 101.96 | DW9: 0 | DX9: 100.55 | DZ9: 100.08 | EA9: 0 | EB9: NCRPechay, Native | EC9: 79.1 | ED9: 0 | EE9: 74.95 | EG9: 75.32 | EH9: 0 | EI9: NCRString Beans | EJ9: 123.28 | EK9: 0 | EL9: 135.08 | EN9: 136.4 | EO9: 0 | EP9: NCRTomato | EQ9: 112.04 | ER9: 0 | ES9: 84.19 | EU9: 75.24 | EV9: 0 | EW9: NCRWhite Potato | EX9: 118.24 | EY9: 0 | EZ9: 124.13 | FB9: 123.32 | FC9: 0 | FE9: NCROnion, Red | FF9: 114.02 | FG9: 0 | FH9: 92.02 | FJ9: 90.85 | FK9: 0 | FL9: NCRGarlic, Native | FM9: 330.5 | FN9: 0 | FO9: 331.1 | FQ9: 333.67 | FR9: 0 | FS9: NCRGarlic, Imported | FT9: 148.08 | FU9: 0 | FV9: 146.81 | FX9: 150.36 | FY9: 0 | FZ9: NCRGinger, Hawaiian | GA9: 131.96 | GB9: 0 | GC9: 127.76 | GE9: 127.84 | GF9: 0 | GH9: NCRBanana, Lakatan | GI9: 101.45 | GJ9: 0 | GK9: 101.62 | GM9: 101.6 | GN9: 0 | GO9: NCRBanana, Latundan | GP9: 0 | GQ9: 0 | GR9: 0 | GT9: 0 | GU9: 0 | GV9: NCRCalamansi | GW9: 103.12 | GX9: 0 | GY9: 94.57 | HA9: 87.71 | HB9: 0 | HC9: NCRMango, Carabao | HD9: 169.44 | HE9: 0 | HF9: 169.26 | HH9: 163.8 | HI9: 0 | HJ9: NCRPapaya | HK9: 0 | HL9: 0 | HM9: 0 | HO9: 0 | HP9: 0 | HR9: NCRCooking oil | HS9: 187.86 | HT9: 0 | HU9: 187.94 | HW9: 187.94 | HX9: 0 | HY9: NCRBrown Sugar | HZ9: 85.84 | IA9: 0 | IB9: 85.72 | ID9: 85.42 | IE9: 0 | IF9: NCRRefined Sugar | IG9: 100.08 | IH9: 0 | II9: 99.87 | IK9: 99.46 | IL9: 0
A10: CAR | B10: CAR - Cordillera Administrative Region | C10: CARRice, Special | D10: 61.16 | E10: 0 | F10: 61.43 | H10: 61.27 | I10: 0 | J10: CARRice, Well Milled | K10: 55.32 | L10: 0 | M10: 56.28 | O10: 56.24 | P10: 0 | Q10: CARRice, Regular Milled | R10: 49.31 | S10: 0 | T10: 50.7 | V10: 50.13 | W10: 0 | Y10: CARFresh Beef, Meat with Bones | Z10: 329.67 | AA10: 0 | AB10: 328.67 | AD10: 329.43 | AE10: 0 | AF10: CARFresh Beef, Pure Meat | AG10: 360.3 | AH10: 0 | AI10: 361.2 | AK10: 361.13 | AL10: 0 | AM10: CARFresh Pork, Kasim | AN10: 294.1 | AO10: 0 | AP10: 294.74 | AR10: 295.1 | AS10: 0 | AT10: CARFresh Pork, Liempo | AU10: 306.02 | AV10: 0 | AW10: 308.6 | AY10: 308.43 | AZ10: 0 | BA10: CARFresh Pork, Meat with Bones | BB10: 288.07 | BC10: 0 | BD10: 289.05 | BF10: 288.95 | BG10: 0 | BH10: CARDressed Chicken | BI10: 200.83 | BJ10: 0 | BK10: 200.6 | BM10: 200.88 | BN10: 0 | BO10: CARChicken egg, med. (piece) | BP10: 9.43 | BQ10: 0 | BR10: 9.09 | BT10: 9.07 | BU10: 0 | BW10: CARBangus | BX10: 207.48 | BY10: 0 | BZ10: 214.02 | CB10: 211.4 | CC10: 0 | CD10: CARGalunggong | CE10: 203.64 | CF10: 0 | CG10: 205.79 | CI10: 201.26 | CJ10: 0 | CK10: CARTilapia | CL10: 162.79 | CM10: 0 | CN10: 162.71 | CP10: 160.6 | CQ10: 0 | CS10: CARAmpalaya | CT10: 90.84 | CU10: 0 | CV10: 89.46 | CX10: 81.35 | CY10: 0 | CZ10: CARCabbage | DA10: 38.68 | DB10: 0 | DC10: 41.74 | DE10: 40.93 | DF10: 0 | DG10: CARCarrot | DH10: 70.73 | DI10: 0 | DJ10: 84.71 | DL10: 87.39 | DM10: 0 | DN10: CAREggplant | DO10: 63.56 | DP10: 0 | DQ10: 65.13 | DS10: 62.16 | DT10: 0 | DU10: CARBaguio Beans | DV10: 67.79 | DW10: 0 | DX10: 79.8 | DZ10: 79.8 | EA10: 0 | EB10: CARPechay, Native | EC10: 50 | ED10: 0 | EE10: 47.5 | EG10: 45 | EH10: 0 | EI10: CARString Beans | EJ10: 83.98 | EK10: 0 | EL10: 91.2 | EN10: 86.81 | EO10: 0 | EP10: CARTomato | EQ10: 78.5 | ER10: 0 | ES10: 69.19 | EU10: 58.47 | EV10: 0 | EW10: CARWhite Potato | EX10: 105.53 | EY10: 0 | EZ10: 114.51 | FB10: 112.21 | FC10: 0 | FE10: CAROnion, Red | FF10: 147.88 | FG10: 0 | FH10: 131.09 | FJ10: 119.93 | FK10: 0 | FL10: CARGarlic, Native | FM10: 165.03 | FN10: 0 | FO10: 161.41 | FQ10: 160.14 | FR10: 0 | FS10: CARGarlic, Imported | FT10: 138.75 | FU10: 0 | FV10: 137.5 | FX10: 138.75 | FY10: 0 | FZ10: CARGinger, Hawaiian | GA10: 98.83 | GB10: 0 | GC10: 93.03 | GE10: 90.76 | GF10: 0 | GH10: CARBanana, Lakatan | GI10: 96.53 | GJ10: 0 | GK10: 95.39 | GM10: 90.67 | GN10: 0 | GO10: CARBanana, Latundan | GP10: 44 | GQ10: 0 | GR10: 44.4 | GT10: 45 | GU10: 0 | GV10: CARCalamansi | GW10: 96.77 | GX10: 0 | GY10: 98.39 | HA10: 98.74 | HB10: 0 | HC10: CARMango, Carabao | HD10: 107.5 | HE10: 0 | HF10: 107.5 | HH10: 100 | HI10: 0 | HJ10: CARPapaya | HK10: 47.4 | HL10: 0 | HM10: 47.25 | HO10: 47.5 | HP10: 0 | HR10: CARCooking oil | HS10: 133 | HT10: 0 | HU10: 133 | HW10: 133 | HX10: 0 | HY10: CARBrown Sugar | HZ10: 71.76 | IA10: 0 | IB10: 70.39 | ID10: 70.55 | IE10: 0 | IF10: CARRefined Sugar | IG10: 84.36 | IH10: 0 | II10: 83.32 | IK10: 83.29 | IL10: 0
A11: 1 | B11: Abra | C11: 1Rice, Special | D11: 55.25 | E11: 0 | F11: 57.25 | H11: 56.25 | I11: 0 | J11: 1Rice, Well Milled | K11: 50.84 | L11: 0 | M11: 57.5 | O11: 56.5 | P11: 0 | Q11: 1Rice, Regular Milled | R11: 42.5 | S11: 0 | T11: 52.5 | V11: 50 | W11: 0 | Y11: 1Fresh Beef, Meat with Bones | Z11: 280 | AA11: 0 | AB11: 280 | AD11: 280 | AE11: 0 | AF11: 1Fresh Beef, Pure Meat | AG11: 290 | AH11: 0 | AI11: 290 | AK11: 290 | AL11: 0 | AM11: 1Fresh Pork, Kasim | AN11: 260 | AO11: 0 | AP11: 260 | AR11: 260 | AS11: 0 | AT11: 1Fresh Pork, Liempo | AU11: 260 | AV11: 0 | AW11: 260 | AY11: 260 | AZ11: 0 | BA11: 1Fresh Pork, Meat with Bones | BB11: 250 | BC11: 0 | BD11: 250 | BF11: 250 | BG11: 0 | BH11: 1Dressed Chicken | BI11: 210 | BJ11: 0 | BK11: 210 | BM11: 210 | BN11: 0 | BO11: 1Chicken egg, med. (piece) | BP11: 8 | BQ11: 0 | BR11: 8 | BT11: 8 | BU11: 0 | BW11: 1Bangus | BX11: 210 | BY11: 0 | BZ11: 245 | CB11: 245 | CC11: 0 | CD11: 1Galunggong | CE11: 210 | CF11: 0 | CG11: 220 | CI11: 220 | CJ11: 0 | CK11: 1Tilapia | CL11: 160 | CM11: 0 | CN11: 170 | CP11: 170 | CQ11: 0 | CS11: 1Ampalaya | CT11: 75 | CU11: 0 | CV11: 80 | CX11: 60 | CY11: 0 | CZ11: 1Cabbage | DA11: 32.5 | DB11: 0 | DC11: 40 | DE11: 37.5 | DF11: 0 | DG11: 1Carrot | DH11: 80 | DI11: 0 | DJ11: 100 | DL11: 100 | DM11: 0 | DN11: 1Eggplant | DO11: 60 | DP11: 0 | DQ11: 55 | DS11: 40 | DT11: 0 | DU11: 1Baguio Beans | DV11: 0 | DW11: 0 | DX11: 0 | DZ11: 0 | EA11: 0 | EB11: 1Pechay, Native | EC11: 0 | ED11: 0 | EE11: 0 | EG11: 0 | EH11: 0 | EI11: 1String Beans | EJ11: 100 | EK11: 0 | EL11: 95 | EN11: 90 | EO11: 0 | EP11: 1Tomato | EQ11: 60 | ER11: 0 | ES11: 45 | EU11: 40 | EV11: 0 | EW11: 1White Potato | EX11: 90 | EY11: 0 | EZ11: 120 | FB11: 100 | FC11: 0 | FE11: 1Onion, Red | FF11: 130 | FG11: 0 | FH11: 120 | FJ11: 120 | FK11: 0 | FL11: 1Garlic, Native | FM11: 140 | FN11: 0 | FO11: 140 | FQ11: 140 | FR11: 0 | FS11: 1Garlic, Imported | FT11: 0 | FU11: 0 | FV11: 0 | FX11: 0 | FY11: 0 | FZ11: 1Ginger, Hawaiian | GA11: 110 | GB11: 0 | GC11: 85 | GE11: 90 | GF11: 0 | GH11: 1Banana, Lakatan | GI11: 125 | GJ11: 0 | GK11: 125 | GM11: 100 | GN11: 0 | GO11: 1Banana, Latundan | GP11: 75 | GQ11: 0 | GR11: 75 | GT11: 75 | GU11: 0 | GV11: 1Calamansi | GW11: 100 | GX11: 0 | GY11: 100 | HA11: 100 | HB11: 0 | HC11: 1Mango, Carabao | HD11: 80 | HE11: 0 | HF11: 80 | HH11: 80 | HI11: 0 | HJ11: 1Papaya | HK11: 37.5 | HL11: 0 | HM11: 37.5 | HO11: 37.5 | HP11: 0 | HR11: 1Cooking oil | HS11: 0 | HT11: 0 | HU11: 0 | HW11: 0 | HX11: 0 | HY11: 1Brown Sugar | HZ11: 77 | IA11: 0 | IB11: 73 | ID11: 73 | IE11: 0 | IF11: 1Refined Sugar | IG11: 0 | IH11: 0 | II11: 0 | IK11: 0 | IL11: 0
A12: 81 | B12: Apayao | C12: 81Rice, Special | D12: 60 | E12: 0 | F12: 58 | H12: 58 | I12: 0 | J12: 81Rice, Well Milled | K12: 58 | L12: 0 | M12: 54.5 | O12: 55 | P12: 0 | Q12: 81Rice, Regular Milled | R12: 56 | S12: 0 | T12: 54 | V12: 52 | W12: 0 | Y12: 81Fresh Beef, Meat with Bones | Z12: 260 | AA12: 0 | AB12: 260 | AD12: 260 | AE12: 0 | AF12: 81Fresh Beef, Pure Meat | AG12: 285 | AH12: 0 | AI12: 285 | AK12: 285 | AL12: 0 | AM12: 81Fresh Pork, Kasim | AN12: 255 | AO12: 0 | AP12: 255 | AR12: 255 | AS12: 0 | AT12: 81Fresh Pork, Liempo | AU12: 255 | AV12: 0 | AW12: 255 | AY12: 255 | AZ12: 0 | BA12: 81Fresh Pork, Meat with Bones | BB12: 255 | BC12: 0 | BD12: 255 | BF12: 255 | BG12: 0 | BH12: 81Dressed Chicken | BI12: 180 | BJ12: 0 | BK12: 180 | BM12: 180 | BN12: 0 | BO12: 81Chicken egg, med. (piece) | BP12: 10 | BQ12: 0 | BR12: 8 | BT12: 8 | BU12: 0 | BW12: 81Bangus | BX12: 185 | BY12: 0 | BZ12: 187.5 | CB12: 187.5 | CC12: 0 | CD12: 81Galunggong | CE12: 170 | CF12: 0 | CG12: 170 | CI12: 170 | CJ12: 0 | CK12: 81Tilapia | CL12: 155 | CM12: 0 | CN12: 150 | CP12: 150 | CQ12: 0 | CS12: 81Ampalaya | CT12: 65 | CU12: 0 | CV12: 80 | CX12: 80 | CY12: 0 | CZ12: 81Cabbage | DA12: 35 | DB12: 0 | DC12: 32.5 | DE12: 32.5 | DF12: 0 | DG12: 81Carrot | DH12: 65 | DI12: 0 | DJ12: 85 | DL12: 85 | DM12: 0 | DN12: 81Eggplant | DO12: 45 | DP12: 0 | DQ12: 55 | DS12: 50 | DT12: 0 | DU12: 81Baguio Beans | DV12: 0 | DW12: 0 | DX12: 0 | DZ12: 0 | EA12: 0 | EB12: 81Pechay, Native | EC12: 0 | ED12: 0 | EE12: 0 | EG12: 0 | EH12: 0 | EI12: 81String Beans | EJ12: 60 | EK12: 0 | EL12: 70 | EN12: 70 | EO12: 0 | EP12: 81Tomato | EQ12: 87.5 | ER12: 0 | ES12: 65 | EU12: 55 | EV12: 0 | EW12: 81White Potato | EX12: 95 | EY12: 0 | EZ12: 95 | FB12: 95 | FC12: 0 | FE12: 81Onion, Red | FF12: 110 | FG12: 0 | FH12: 110 | FJ12: 110 | FK12: 0 | FL12: 81Garlic, Native | FM12: 0 | FN12: 0 | FO12: 0 | FQ12: 0 | FR12: 0 | FS12: 81Garlic, Imported | FT12: 135 | FU12: 0 | FV12: 135 | FX12: 135 | FY12: 0 | FZ12: 81Ginger, Hawaiian | GA12: 65 | GB12: 0 | GC12: 65 | GE12: 65 | GF12: 0 | GH12: 81Banana, Lakatan | GI12: 55 | GJ12: 0 | GK12: 55 | GM12: 55 | GN12: 0 | GO12: 81Banana, Latundan | GP12: 25 | GQ12: 0 | GR12: 25 | GT12: 25 | GU12: 0 | GV12: 81Calamansi | GW12: 90 | GX12: 0 | GY12: 90 | HA12: 90 | HB12: 0 | HC12: 81Mango, Carabao | HD12: 0 | HE12: 0 | HF12: 0 | HH12: 0 | HI12: 0 | HJ12: 81Papaya | HK12: 0 | HL12: 0 | HM12: 0 | HO12: 0 | HP12: 0 | HR12: 81Cooking oil | HS12: 0 | HT12: 0 | HU12: 0 | HW12: 0 | HX12: 0 | HY12: 81Brown Sugar | HZ12: 66 | IA12: 0 | IB12: 66 | ID12: 66 | IE12: 0 | IF12: 81Refined Sugar | IG12: 88.5 | IH12: 0 | II12: 88.5 | IK12: 88.5 | IL12: 0
A13: 11 | B13: Benguet | C13: 11Rice, Special | D13: 61.13 | E13: 0 | F13: 61.22 | H13: 61.22 | I13: 0 | J13: 11Rice, Well Milled | K13: 51.38 | L13: 0 | M13: 51.38 | O13: 51.38 | P13: 0 | Q13: 11Rice, Regular Milled | R13: 41 | S13: 0 | T13: 41 | V13: 41 | W13: 0 | Y13: 11Fresh Beef, Meat with Bones | Z13: 380 | AA13: 0 | AB13: 371 | AD13: 371 | AE13: 0 | AF13: 11Fresh Beef, Pure Meat | AG13: 431.5 | AH13: 0 | AI13: 433.5 | AK13: 433.5 | AL13: 0 | AM13: 11Fresh Pork, Kasim | AN13: 284 | AO13: 0 | AP13: 284 | AR13: 284 | AS13: 0 | AT13: 11Fresh Pork, Liempo | AU13: 324 | AV13: 0 | AW13: 324 | AY13: 324 | AZ13: 0 | BA13: 11Fresh Pork, Meat with Bones | BB13: 274 | BC13: 0 | BD13: 274 | BF13: 274 | BG13: 0 | BH13: 11Dressed Chicken | BI13: 202.5 | BJ13: 0 | BK13: 202.5 | BM13: 202.5 | BN13: 0 | BO13: 11Chicken egg, med. (piece) | BP13: 9.25 | BQ13: 0 | BR13: 9.25 | BT13: 9.25 | BU13: 0 | BW13: 11Bangus | BX13: 200 | BY13: 0 | BZ13: 205 | CB13: 205 | CC13: 0 | CD13: 11Galunggong | CE13: 252.5 | CF13: 0 | CG13: 252.5 | CI13: 235 | CJ13: 0 | CK13: 11Tilapia | CL13: 157.5 | CM13: 0 | CN13: 157.5 | CP13: 157.5 | CQ13: 0 | CS13: 11Ampalaya | CT13: 92.5 | CU13: 0 | CV13: 92.5 | CX13: 67.5 | CY13: 0 | CZ13: 11Cabbage | DA13: 45 | DB13: 0 | DC13: 51 | DE13: 50 | DF13: 0 | DG13: 11Carrot | DH13: 55 | DI13: 0 | DJ13: 55 | DL13: 65 | DM13: 0 | DN13: 11Eggplant | DO13: 82.5 | DP13: 0 | DQ13: 82.5 | DS13: 72.5 | DT13: 0 | DU13: 11Baguio Beans | DV13: 67.5 | DW13: 0 | DX13: 67.5 | DZ13: 75 | EA13: 0 | EB13: 11Pechay, Native | EC13: 0 | ED13: 0 | EE13: 0 | EG13: 0 | EH13: 0 | EI13: 11String Beans | EJ13: 90 | EK13: 0 | EL13: 90 | EN13: 90 | EO13: 0 | EP13: 11Tomato | EQ13: 80 | ER13: 0 | ES13: 80 | EU13: 70 | EV13: 0 | EW13: 11White Potato | EX13: 110 | EY13: 0 | EZ13: 134 | FB13: 134 | FC13: 0 | FE13: 11Onion, Red | FF13: 185 | FG13: 0 | FH13: 185 | FJ13: 135 | FK13: 0 | FL13: 11Garlic, Native | FM13: 180 | FN13: 0 | FO13: 175 | FQ13: 175 | FR13: 0 | FS13: 11Garlic, Imported | FT13: 0 | FU13: 0 | FV13: 0 | FX13: 0 | FY13: 0 | FZ13: 11Ginger, Hawaiian | GA13: 100 | GB13: 0 | GC13: 95 | GE13: 90 | GF13: 0 | GH13: 11Banana, Lakatan | GI13: 106.5 | GJ13: 0 | GK13: 106.5 | GM13: 106.5 | GN13: 0 | GO13: 11Banana, Latundan | GP13: 0 | GQ13: 0 | GR13: 0 | GT13: 0 | GU13: 0 | GV13: 11Calamansi | GW13: 100 | GX13: 0 | GY13: 110 | HA13: 110 | HB13: 0 | HC13: 11Mango, Carabao | HD13: 0 | HE13: 0 | HF13: 0 | HH13: 0 | HI13: 0 | HJ13: 11Papaya | HK13: 51.5 | HL13: 0 | HM13: 51.5 | HO13: 51.5 | HP13: 0 | HR13: 11Cooking oil | HS13: 0 | HT13: 0 | HU13: 0 | HW13: 0 | HX13: 0 | HY13: 11Brown Sugar | HZ13: 76 | IA13: 0 | IB13: 76 | ID13: 77.5 | IE13: 0 | IF13: 11Refined Sugar | IG13: 89 | IH13: 0 | II13: 89 | IK13: 90.5 | IL13: 0
A14: 27 | B14: Ifugao | C14: 27Rice, Special | D14: 0 | E14: 0 | F14: 0 | H14: 0 | I14: 0 | J14: 27Rice, Well Milled | K14: 58.5 | L14: 0 | M14: 58.58 | O14: 58.58 | P14: 0 | Q14: 27Rice, Regular Milled | R14: 51 | S14: 0 | T14: 51 | V14: 51 | W14: 0 | Y14: 27Fresh Beef, Meat with Bones | Z14: 310 | AA14: 0 | AB14: 310 | AD14: 310 | AE14: 0 | AF14: 27Fresh Beef, Pure Meat | AG14: 350 | AH14: 0 | AI14: 350 | AK14: 350 | AL14: 0 | AM14: 27Fresh Pork, Kasim | AN14: 330 | AO14: 0 | AP14: 335 | AR14: 335 | AS14: 0 | AT14: 27Fresh Pork, Liempo | AU14: 330 | AV14: 0 | AW14: 335 | AY14: 335 | AZ14: 0 | BA14: 27Fresh Pork, Meat with Bones | BB14: 330 | BC14: 0 | BD14: 330 | BF14: 335 | BG14: 0 | BH14: 27Dressed Chicken | BI14: 220 | BJ14: 0 | BK14: 220 | BM14: 220 | BN14: 0 | BO14: 27Chicken egg, med. (piece) | BP14: 9.5 | BQ14: 0 | BR14: 9.5 | BT14: 9 | BU14: 0 | BW14: 27Bangus | BX14: 240 | BY14: 0 | BZ14: 240 | CB14: 230 | CC14: 0 | CD14: 27Galunggong | CE14: 175 | CF14: 0 | CG14: 175 | CI14: 165 | CJ14: 0 | CK14: 27Tilapia | CL14: 170 | CM14: 0 | CN14: 170 | CP14: 160 | CQ14: 0 | CS14: 27Ampalaya | CT14: 90 | CU14: 0 | CV14: 65 | CX14: 75 | CY14: 0 | CZ14: 27Cabbage | DA14: 40 | DB14: 0 | DC14: 40 | DE14: 40 | DF14: 0 | DG14: 27Carrot | DH14: 80 | DI14: 0 | DJ14: 100 | DL14: 100 | DM14: 0 | DN14: 27Eggplant | DO14: 55 | DP14: 0 | DQ14: 50 | DS14: 60 | DT14: 0 | DU14: 27Baguio Beans | DV14: 50 | DW14: 0 | DX14: 55 | DZ14: 65 | EA14: 0 | EB14: 27Pechay, Native | EC14: 0 | ED14: 0 | EE14: 0 | EG14: 0 | EH14: 0 | EI14: 27String Beans | EJ14: 0 | EK14: 0 | EL14: 0 | EN14: 0 | EO14: 0 | EP14: 27Tomato | EQ14: 80 | ER14: 0 | ES14: 70 | EU14: 50 | EV14: 0 | EW14: 27White Potato | EX14: 100 | EY14: 0 | EZ14: 120 | FB14: 110 | FC14: 0 | FE14: 27Onion, Red | FF14: 155 | FG14: 0 | FH14: 140 | FJ14: 130 | FK14: 0 | FL14: 27Garlic, Native | FM14: 145 | FN14: 0 | FO14: 145 | FQ14: 145 | FR14: 0 | FS14: 27Garlic, Imported | FT14: 0 | FU14: 0 | FV14: 0 | FX14: 0 | FY14: 0 | FZ14: 27Ginger, Hawaiian | GA14: 70 | GB14: 0 | GC14: 70 | GE14: 65 | GF14: 0 | GH14: 27Banana, Lakatan | GI14: 80 | GJ14: 0 | GK14: 80 | GM14: 80 | GN14: 0 | GO14: 27Banana, Latundan | GP14: 40 | GQ14: 0 | GR14: 40 | GT14: 40 | GU14: 0 | GV14: 27Calamansi | GW14: 95 | GX14: 0 | GY14: 100 | HA14: 100 | HB14: 0 | HC14: 27Mango, Carabao | HD14: 0 | HE14: 0 | HF14: 0 | HH14: 0 | HI14: 0 | HJ14: 27Papaya | HK14: 40 | HL14: 0 | HM14: 40 | HO14: 40 | HP14: 0 | HR14: 27Cooking oil | HS14: 133 | HT14: 0 | HU14: 133 | HW14: 133 | HX14: 0 | HY14: 27Brown Sugar | HZ14: 68 | IA14: 0 | IB14: 68 | ID14: 68 | IE14: 0 | IF14: 27Refined Sugar | IG14: 80 | IH14: 0 | II14: 80 | IK14: 80 | IL14: 0
A15: 32 | B15: Kalinga | C15: 32Rice, Special | D15: 60 | E15: 0 | F15: 60.5 | H15: 60.5 | I15: 0 | J15: 32Rice, Well Milled | K15: 54 | L15: 0 | M15: 55.5 | O15: 56 | P15: 0 | Q15: 32Rice, Regular Milled | R15: 49 | S15: 0 | T15: 50 | V15: 50.5 | W15: 0 | Y15: 32Fresh Beef, Meat with Bones | Z15: 340 | AA15: 0 | AB15: 340 | AD15: 340 | AE15: 0 | AF15: 32Fresh Beef, Pure Meat | AG15: 0 | AH15: 0 | AI15: 0 | AK15: 0 | AL15: 0 | AM15: 32Fresh Pork, Kasim | AN15: 300 | AO15: 0 | AP15: 300 | AR15: 300 | AS15: 0 | AT15: 32Fresh Pork, Liempo | AU15: 300 | AV15: 0 | AW15: 300 | AY15: 300 | AZ15: 0 | BA15: 32Fresh Pork, Meat with Bones | BB15: 285 | BC15: 0 | BD15: 285 | BF15: 285 | BG15: 0 | BH15: 32Dressed Chicken | BI15: 200 | BJ15: 0 | BK15: 200 | BM15: 200 | BN15: 0 | BO15: 32Chicken egg, med. (piece) | BP15: 0 | BQ15: 0 | BR15: 0 | BT15: 0 | BU15: 0 | BW15: 32Bangus | BX15: 190 | BY15: 0 | BZ15: 195 | CB15: 195 | CC15: 0 | CD15: 32Galunggong | CE15: 192.5 | CF15: 0 | CG15: 195 | CI15: 195 | CJ15: 0 | CK15: 32Tilapia | CL15: 165 | CM15: 0 | CN15: 165 | CP15: 165 | CQ15: 0 | CS15: 32Ampalaya | CT15: 85 | CU15: 0 | CV15: 70 | CX15: 70 | CY15: 0 | CZ15: 32Cabbage | DA15: 17.5 | DB15: 0 | DC15: 27.5 | DE15: 25 | DF15: 0 | DG15: 32Carrot | DH15: 50 | DI15: 0 | DJ15: 65 | DL15: 75 | DM15: 0 | DN15: 32Eggplant | DO15: 35 | DP15: 0 | DQ15: 37.5 | DS15: 37.5 | DT15: 0 | DU15: 32Baguio Beans | DV15: 55 | DW15: 0 | DX15: 65 | DZ15: 70 | EA15: 0 | EB15: 32Pechay, Native | EC15: 50 | ED15: 0 | EE15: 47.5 | EG15: 45 | EH15: 0 | EI15: 32String Beans | EJ15: 60 | EK15: 0 | EL15: 65 | EN15: 62.5 | EO15: 0 | EP15: 32Tomato | EQ15: 65 | ER15: 0 | ES15: 52.5 | EU15: 37.5 | EV15: 0 | EW15: 32White Potato | EX15: 100 | EY15: 0 | EZ15: 95 | FB15: 100 | FC15: 0 | FE15: 32Onion, Red | FF15: 135 | FG15: 0 | FH15: 80 | FJ15: 75 | FK15: 0 | FL15: 32Garlic, Native | FM15: 0 | FN15: 0 | FO15: 0 | FQ15: 0 | FR15: 0 | FS15: 32Garlic, Imported | FT15: 142.5 | FU15: 0 | FV15: 140 | FX15: 142.5 | FY15: 0 | FZ15: 32Ginger, Hawaiian | GA15: 80 | GB15: 0 | GC15: 80 | GE15: 70 | GF15: 0 | GH15: 32Banana, Lakatan | GI15: 0 | GJ15: 0 | GK15: 0 | GM15: 0 | GN15: 0 | GO15: 32Banana, Latundan | GP15: 25 | GQ15: 0 | GR15: 27 | GT15: 30 | GU15: 0 | GV15: 32Calamansi | GW15: 57.5 | GX15: 0 | GY15: 62.5 | HA15: 70 | HB15: 0 | HC15: 32Mango, Carabao | HD15: 0 | HE15: 0 | HF15: 0 | HH15: 0 | HI15: 0 | HJ15: 32Papaya | HK15: 0 | HL15: 0 | HM15: 0 | HO15: 0 | HP15: 0 | HR15: 32Cooking oil | HS15: 0 | HT15: 0 | HU15: 0 | HW15: 0 | HX15: 0 | HY15: 32Brown Sugar | HZ15: 72.5 | IA15: 0 | IB15: 69 | ID15: 66.5 | IE15: 0 | IF15: 32Refined Sugar | IG15: 87 | IH15: 0 | II15: 81.5 | IK15: 77.5 | IL15: 0
A16: 44 | B16: Mountain Province | C16: 44Rice, Special | D16: 65 | E16: 0 | F16: 65 | H16: 65 | I16: 0 | J16: 44Rice, Well Milled | K16: 58 | L16: 0 | M16: 60 | O16: 60 | P16: 0 | Q16: 44Rice, Regular Milled | R16: 55 | S16: 0 | T16: 56 | V16: 56 | W16: 0 | Y16: 44Fresh Beef, Meat with Bones | Z16: 340 | AA16: 0 | AB16: 340 | AD16: 340 | AE16: 0 | AF16: 44Fresh Beef, Pure Meat | AG16: 0 | AH16: 0 | AI16: 0 | AK16: 0 | AL16: 0 | AM16: 44Fresh Pork, Kasim | AN16: 300 | AO16: 0 | AP16: 300 | AR16: 300 | AS16: 0 | AT16: 44Fresh Pork, Liempo | AU16: 300 | AV16: 0 | AW16: 300 | AY16: 300 | AZ16: 0 | BA16: 44Fresh Pork, Meat with Bones | BB16: 300 | BC16: 0 | BD16: 300 | BF16: 300 | BG16: 0 | BH16: 44Dressed Chicken | BI16: 205 | BJ16: 0 | BK16: 205 | BM16: 205 | BN16: 0 | BO16: 44Chicken egg, med. (piece) | BP16: 11.5 | BQ16: 0 | BR16: 11.5 | BT16: 12 | BU16: 0 | BW16: 44Bangus | BX16: 225 | BY16: 0 | BZ16: 222.5 | CB16: 222.5 | CC16: 0 | CD16: 44Galunggong | CE16: 177.5 | CF16: 0 | CG16: 177.5 | CI16: 177.5 | CJ16: 0 | CK16: 44Tilapia | CL16: 180 | CM16: 0 | CN16: 180 | CP16: 180 | CQ16: 0 | CS16: 44Ampalaya | CT16: 120 | CU16: 0 | CV16: 130 | CX16: 110 | CY16: 0 | CZ16: 44Cabbage | DA16: 45 | DB16: 0 | DC16: 45 | DE16: 45 | DF16: 0 | DG16: 44Carrot | DH16: 70 | DI16: 0 | DJ16: 90 | DL16: 80 | DM16: 0 | DN16: 44Eggplant | DO16: 80 | DP16: 0 | DQ16: 90 | DS16: 90 | DT16: 0 | DU16: 44Baguio Beans | DV16: 80 | DW16: 0 | DX16: 120 | DZ16: 100 | EA16: 0 | EB16: 44Pechay, Native | EC16: 0 | ED16: 0 | EE16: 0 | EG16: 0 | EH16: 0 | EI16: 44String Beans | EJ16: 80 | EK16: 0 | EL16: 120 | EN16: 100 | EO16: 0 | EP16: 44Tomato | EQ16: 80 | ER16: 0 | ES16: 90 | EU16: 80 | EV16: 0 | EW16: 44White Potato | EX16: 130 | EY16: 0 | EZ16: 125 | FB16: 125 | FC16: 0 | FE16: 44Onion, Red | FF16: 200 | FG16: 0 | FH16: 160 | FJ16: 160 | FK16: 0 | FL16: 44Garlic, Native | FM16: 0 | FN16: 0 | FO16: 0 | FQ16: 0 | FR16: 0 | FS16: 44Garlic, Imported | FT16: 0 | FU16: 0 | FV16: 0 | FX16: 0 | FY16: 0 | FZ16: 44Ginger, Hawaiian | GA16: 120 | GB16: 0 | GC16: 120 | GE16: 120 | GF16: 0 | GH16: 44Banana, Lakatan | GI16: 90 | GJ16: 0 | GK16: 85 | GM16: 80 | GN16: 0 | GO16: 44Banana, Latundan | GP16: 55 | GQ16: 0 | GR16: 55 | GT16: 55 | GU16: 0 | GV16: 44Calamansi | GW16: 120 | GX16: 0 | GY16: 130 | HA16: 130 | HB16: 0 | HC16: 44Mango, Carabao | HD16: 135 | HE16: 0 | HF16: 135 | HH16: 120 | HI16: 0 | HJ16: 44Papaya | HK16: 0 | HL16: 0 | HM16: 0 | HO16: 0 | HP16: 0 | HR16: 44Cooking oil | HS16: 0 | HT16: 0 | HU16: 0 | HW16: 0 | HX16: 0 | HY16: 44Brown Sugar | HZ16: 70 | IA16: 0 | IB16: 70 | ID16: 72.5 | IE16: 0 | IF16: 44Refined Sugar | IG16: 80 | IH16: 0 | II16: 80 | IK16: 82.5 | IL16: 0
A17: 1102 | B17: City of Baguio | C17: 1102Rice, Special | D17: 65.56 | E17: 0 | F17: 66.58 | H17: 66.65 | I17: 0 | J17: 1102Rice, Well Milled | K17: 56.5 | L17: 0 | M17: 56.52 | O17: 56.22 | P17: 0 | Q17: 1102Rice, Regular Milled | R17: 50.67 | S17: 0 | T17: 50.42 | V17: 50.42 | W17: 0 | Y17: 1102Fresh Beef, Meat with Bones | Z17: 397.67 | AA17: 0 | AB17: 399.67 | AD17: 405 | AE17: 0 | AF17: 1102Fresh Beef, Pure Meat | AG17: 445 | AH17: 0 | AI17: 447.5 | AK17: 447.17 | AL17: 0 | AM17: 1102Fresh Pork, Kasim | AN17: 329.67 | AO17: 0 | AP17: 329.17 | AR17: 331.67 | AS17: 0 | AT17: 1102Fresh Pork, Liempo | AU17: 373.17 | AV17: 0 | AW17: 386.17 | AY17: 385 | AZ17: 0 | BA17: 1102Fresh Pork, Meat with Bones | BB17: 322.5 | BC17: 0 | BD17: 329.33 | BF17: 323.67 | BG17: 0 | BH17: 1102Dressed Chicken | BI17: 188.33 | BJ17: 0 | BK17: 186.67 | BM17: 188.67 | BN17: 0 | BO17: 1102Chicken egg, med. (piece) | BP17: 8.32 | BQ17: 0 | BR17: 8.29 | BT17: 8.17 | BU17: 0 | BW17: 1102Bangus | BX17: 202.33 | BY17: 0 | BZ17: 203.17 | CB17: 194.83 | CC17: 0 | CD17: 1102Galunggong | CE17: 248 | CF17: 0 | CG17: 250.5 | CI17: 246.33 | CJ17: 0 | CK17: 1102Tilapia | CL17: 152 | CM17: 0 | CN17: 146.5 | CP17: 141.67 | CQ17: 0 | CS17: 1102Ampalaya | CT17: 108.38 | CU17: 0 | CV17: 108.71 | CX17: 106.96 | CY17: 0 | CZ17: 1102Cabbage | DA17: 55.75 | DB17: 0 | DC17: 56.17 | DE17: 56.5 | DF17: 0 | DG17: 1102Carrot | DH17: 95.08 | DI17: 0 | DJ17: 98 | DL17: 106.75 | DM17: 0 | DN17: 1102Eggplant | DO17: 87.42 | DP17: 0 | DQ17: 85.92 | DS17: 85.13 | DT17: 0 | DU17: 1102Baguio Beans | DV17: 86.46 | DW17: 0 | DX17: 91.5 | DZ17: 89 | EA17: 0 | EB17: 1102Pechay, Native | EC17: 0 | ED17: 0 | EE17: 0 | EG17: 0 | EH17: 0 | EI17: 1102String Beans | EJ17: 113.88 | EK17: 0 | EL17: 107.17 | EN17: 108.33 | EO17: 0 | EP17: 1102Tomato | EQ17: 97 | ER17: 0 | ES17: 81.8 | EU17: 76.8 | EV17: 0 | EW17: 1102White Potato | EX17: 113.71 | EY17: 0 | EZ17: 112.54 | FB17: 121.5 | FC17: 0 | FE17: 1102Onion, Red | FF17: 120.13 | FG17: 0 | FH17: 122.63 | FJ17: 109.5 | FK17: 0 | FL17: 1102Garlic, Native | FM17: 195.13 | FN17: 0 | FO17: 185.63 | FQ17: 180.54 | FR17: 0 | FS17: 1102Garlic, Imported | FT17: 0 | FU17: 0 | FV17: 0 | FX17: 0 | FY17: 0 | FZ17: 1102Ginger, Hawaiian | GA17: 146.8 | GB17: 0 | GC17: 136.2 | GE17: 135.3 | GF17: 0 | GH17: 1102Banana, Lakatan | GI17: 122.67 | GJ17: 0 | GK17: 120.83 | GM17: 122.5 | GN17: 0 | GO17: 1102Banana, Latundan | GP17: 0 | GQ17: 0 | GR17: 0 | GT17: 0 | GU17: 0 | GV17: 1102Calamansi | GW17: 114.9 | GX17: 0 | GY17: 96.2 | HA17: 91.15 | HB17: 0 | HC17: 1102Mango, Carabao | HD17: 0 | HE17: 0 | HF17: 0 | HH17: 0 | HI17: 0 | HJ17: 1102Papaya | HK17: 60.6 | HL17: 0 | HM17: 60 | HO17: 61 | HP17: 0 | HR17: 1102Cooking oil | HS17: 0 | HT17: 0 | HU17: 0 | HW17: 0 | HX17: 0 | HY17: 1102Brown Sugar | HZ17: 72.79 | IA17: 0 | IB17: 70.71 | ID17: 70.33 | IE17: 0 | IF17: 1102Refined Sugar | IG17: 81.67 | IH17: 0 | II17: 80.92 | IK17: 80.75 | IL17: 0
A18: R1 | B18: I - Ilocos Region | C18: R1Rice, Special | D18: 61.81 | E18: 0 | F18: 61.77 | H18: 62.15 | I18: 0 | J18: R1Rice, Well Milled | K18: 52.76 | L18: 0 | M18: 52.89 | O18: 52.89 | P18: 0 | Q18: R1Rice, Regular Milled | R18: 49 | S18: 0 | T18: 49.5 | V18: 49.5 | W18: 0 | Y18: R1Fresh Beef, Meat with Bones | Z18: 333.63 | AA18: 0 | AB18: 329.88 | AD18: 333.63 | AE18: 0 | AF18: R1Fresh Beef, Pure Meat | AG18: 398.67 | AH18: 0 | AI18: 414.83 | AK18: 414.83 | AL18: 0 | AM18: R1Fresh Pork, Kasim | AN18: 321.75 | AO18: 0 | AP18: 326.75 | AR18: 324.25 | AS18: 0 | AT18: R1Fresh Pork, Liempo | AU18: 334.75 | AV18: 0 | AW18: 342.25 | AY18: 341 | AZ18: 0 | BA18: R1Fresh Pork, Meat with Bones | BB18: 295.25 | BC18: 0 | BD18: 299 | BF18: 297.75 | BG18: 0 | BH18: R1Dressed Chicken | BI18: 204.38 | BJ18: 0 | BK18: 204.38 | BM18: 205.63 | BN18: 0 | BO18: R1Chicken egg, med. (piece) | BP18: 8.56 | BQ18: 0 | BR18: 8.44 | BT18: 8.44 | BU18: 0 | BW18: R1Bangus | BX18: 207.5 | BY18: 0 | BZ18: 192.5 | CB18: 192.5 | CC18: 0 | CD18: R1Galunggong | CE18: 220 | CF18: 0 | CG18: 226.25 | CI18: 227.5 | CJ18: 0 | CK18: R1Tilapia | CL18: 141.88 | CM18: 0 | CN18: 139.38 | CP18: 141.25 | CQ18: 0 | CS18: R1Ampalaya | CT18: 80 | CU18: 0 | CV18: 87.5 | CX18: 82.5 | CY18: 0 | CZ18: R1Cabbage | DA18: 40.63 | DB18: 0 | DC18: 42.5 | DE18: 43.75 | DF18: 0 | DG18: R1Carrot | DH18: 99.38 | DI18: 0 | DJ18: 123.13 | DL18: 117.5 | DM18: 0 | DN18: R1Eggplant | DO18: 59.75 | DP18: 0 | DQ18: 47.75 | DS18: 49.5 | DT18: 0 | DU18: R1Baguio Beans | DV18: 95 | DW18: 0 | DX18: 85 | DZ18: 87.5 | EA18: 0 | EB18: R1Pechay, Native | EC18: 58.22 | ED18: 0 | EE18: 56.97 | EG18: 55.72 | EH18: 0 | EI18: R1String Beans | EJ18: 90 | EK18: 0 | EL18: 86.67 | EN18: 71.67 | EO18: 0 | EP18: R1Tomato | EQ18: 65 | ER18: 0 | ES18: 42.38 | EU18: 35 | EV18: 0 | EW18: R1White Potato | EX18: 120 | EY18: 0 | EZ18: 125.63 | FB18: 122.5 | FC18: 0 | FE18: R1Onion, Red | FF18: 103.33 | FG18: 0 | FH18: 84.17 | FJ18: 78.33 | FK18: 0 | FL18: R1Garlic, Native | FM18: 315 | FN18: 0 | FO18: 321.67 | FQ18: 296.67 | FR18: 0 | FS18: R1Garlic, Imported | FT18: 145 | FU18: 0 | FV18: 145 | FX18: 145 | FY18: 0 | FZ18: R1Ginger, Hawaiian | GA18: 88.5 | GB18: 0 | GC18: 80.13 | GE18: 83.75 | GF18: 0 | GH18: R1Banana, Lakatan | GI18: 110.83 | GJ18: 0 | GK18: 109.17 | GM18: 106.67 | GN18: 0 | GO18: R1Banana, Latundan | GP18: 63.33 | GQ18: 0 | GR18: 71.67 | GT18: 68.33 | GU18: 0 | GV18: R1Calamansi | GW18: 81.88 | GX18: 0 | GY18: 74.38 | HA18: 71.25 | HB18: 0 | HC18: R1Mango, Carabao | HD18: 160 | HE18: 0 | HF18: 145 | HH18: 157.5 | HI18: 0 | HJ18: R1Papaya | HK18: 61.25 | HL18: 0 | HM18: 61.25 | HO18: 58.13 | HP18: 0 | HR18: R1Cooking oil | HS18: 112.68 | HT18: 0 | HU18: 112.68 | HW18: 112.68 | HX18: 0 | HY18: R1Brown Sugar | HZ18: 81.05 | IA18: 0 | IB18: 78.3 | ID18: 78.3 | IE18: 0 | IF18: R1Refined Sugar | IG18: 88.5 | IH18: 0 | II18: 87.25 | IK18: 87.25 | IL18: 0
A19: 28 | B19: Ilocos Norte | C19: 28Rice, Special | D19: 65 | E19: 0 | F19: 65 | H19: 65 | I19: 0 | J19: 28Rice, Well Milled | K19: 52.54 | L19: 0 | M19: 52.54 | O19: 52.54 | P19: 0 | Q19: 28Rice, Regular Milled | R19: 50 | S19: 0 | T19: 50 | V19: 50 | W19: 0 | Y19: 28Fresh Beef, Meat with Bones | Z19: 337.5 | AA19: 0 | AB19: 337.5 | AD19: 337.5 | AE19: 0 | AF19: 28Fresh Beef, Pure Meat | AG19: 433.5 | AH19: 0 | AI19: 433.5 | AK19: 433.5 | AL19: 0 | AM19: 28Fresh Pork, Kasim | AN19: 334.5 | AO19: 0 | AP19: 334.5 | AR19: 324.5 | AS19: 0 | AT19: 28Fresh Pork, Liempo | AU19: 363 | AV19: 0 | AW19: 363 | AY19: 353 | AZ19: 0 | BA19: 28Fresh Pork, Meat with Bones | BB19: 311 | BC19: 0 | BD19: 311 | BF19: 301 | BG19: 0 | BH19: 28Dressed Chicken | BI19: 220 | BJ19: 0 | BK19: 220 | BM19: 220 | BN19: 0 | BO19: 28Chicken egg, med. (piece) | BP19: 9 | BQ19: 0 | BR19: 9 | BT19: 9 | BU19: 0 | BW19: 28Bangus | BX19: 220 | BY19: 0 | BZ19: 220 | CB19: 210 | CC19: 0 | CD19: 28Galunggong | CE19: 200 | CF19: 0 | CG19: 200 | CI19: 200 | CJ19: 0 | CK19: 28Tilapia | CL19: 155 | CM19: 0 | CN19: 155 | CP19: 160 | CQ19: 0 | CS19: 28Ampalaya | CT19: 0 | CU19: 0 | CV19: 0 | CX19: 0 | CY19: 0 | CZ19: 28Cabbage | DA19: 30 | DB19: 0 | DC19: 37.5 | DE19: 40 | DF19: 0 | DG19: 28Carrot | DH19: 85 | DI19: 0 | DJ19: 140 | DL19: 125 | DM19: 0 | DN19: 28Eggplant | DO19: 45 | DP19: 0 | DQ19: 32.5 | DS19: 40 | DT19: 0 | DU19: 28Baguio Beans | DV19: 0 | DW19: 0 | DX19: 0 | DZ19: 0 | EA19: 0 | EB19: 28Pechay, Native | EC19: 0 | ED19: 0 | EE19: 0 | EG19: 0 | EH19: 0 | EI19: 28String Beans | EJ19: 0 | EK19: 0 | EL19: 0 | EN19: 0 | EO19: 0 | EP19: 28Tomato | EQ19: 65 | ER19: 0 | ES19: 35 | EU19: 30 | EV19: 0 | EW19: 28White Potato | EX19: 120 | EY19: 0 | EZ19: 120 | FB19: 135 | FC19: 0 | FE19: 28Onion, Red | FF19: 125 | FG19: 0 | FH19: 100 | FJ19: 80 | FK19: 0 | FL19: 28Garlic, Native | FM19: 0 | FN19: 0 | FO19: 0 | FQ19: 0 | FR19: 0 | FS19: 28Garlic, Imported | FT19: 145 | FU19: 0 | FV19: 145 | FX19: 145 | FY19: 0 | FZ19: 28Ginger, Hawaiian | GA19: 95 | GB19: 0 | GC19: 80 | GE19: 80 | GF19: 0 | GH19: 28Banana, Lakatan | GI19: 95 | GJ19: 0 | GK19: 95 | GM19: 90 | GN19: 0 | GO19: 28Banana, Latundan | GP19: 67.5 | GQ19: 0 | GR19: 70 | GT19: 70 | GU19: 0 | GV19: 28Calamansi | GW19: 80 | GX19: 0 | GY19: 80 | HA19: 75 | HB19: 0 | HC19: 28Mango, Carabao | HD19: 0 | HE19: 0 | HF19: 0 | HH19: 0 | HI19: 0 | HJ19: 28Papaya | HK19: 65 | HL19: 0 | HM19: 65 | HO19: 62.5 | HP19: 0 | HR19: 28Cooking oil | HS19: 0 | HT19: 0 | HU19: 0 | HW19: 0 | HX19: 0 | HY19: 28Brown Sugar | HZ19: 85 | IA19: 0 | IB19: 85 | ID19: 85 | IE19: 0 | IF19: 28Refined Sugar | IG19: 96 | IH19: 0 | II19: 96 | IK19: 96 | IL19: 0
A20: 29 | B20: Ilocos Sur | C20: 29Rice, Special | D20: 59.75 | E20: 0 | F20: 58.58 | H20: 58.58 | I20: 0 | J20: 29Rice, Well Milled | K20: 48.5 | L20: 0 | M20: 51.5 | O20: 51.5 | P20: 0 | Q20: 29Rice, Regular Milled | R20: 46.5 | S20: 0 | T20: 48.5 | V20: 48.5 | W20: 0 | Y20: 29Fresh Beef, Meat with Bones | Z20: 280 | AA20: 0 | AB20: 260 | AD20: 270 | AE20: 0 | AF20: 29Fresh Beef, Pure Meat | AG20: 350 | AH20: 0 | AI20: 350 | AK20: 350 | AL20: 0 | AM20: 29Fresh Pork, Kasim | AN20: 300 | AO20: 0 | AP20: 300 | AR20: 300 | AS20: 0 | AT20: 29Fresh Pork, Liempo | AU20: 300 | AV20: 0 | AW20: 300 | AY20: 300 | AZ20: 0 | BA20: 29Fresh Pork, Meat with Bones | BB20: 255 | BC20: 0 | BD20: 255 | BF20: 260 | BG20: 0 | BH20: 29Dressed Chicken | BI20: 225 | BJ20: 0 | BK20: 225 | BM20: 220 | BN20: 0 | BO20: 29Chicken egg, med. (piece) | BP20: 8.25 | BQ20: 0 | BR20: 8.25 | BT20: 8.25 | BU20: 0 | BW20: 29Bangus | BX20: 235 | BY20: 0 | BZ20: 200 | CB20: 230 | CC20: 0 | CD20: 29Galunggong | CE20: 240 | CF20: 0 | CG20: 220 | CI20: 230 | CJ20: 0 | CK20: 29Tilapia | CL20: 160 | CM20: 0 | CN20: 150 | CP20: 155 | CQ20: 0 | CS20: 29Ampalaya | CT20: 100 | CU20: 0 | CV20: 100 | CX20: 100 | CY20: 0 | CZ20: 29Cabbage | DA20: 37.5 | DB20: 0 | DC20: 40 | DE20: 50 | DF20: 0 | DG20: 29Carrot | DH20: 100 | DI20: 0 | DJ20: 100 | DL20: 110 | DM20: 0 | DN20: 29Eggplant | DO20: 65 | DP20: 0 | DQ20: 55 | DS20: 45 | DT20: 0 | DU20: 29Baguio Beans | DV20: 80 | DW20: 0 | DX20: 90 | DZ20: 100 | EA20: 0 | EB20: 29Pechay, Native | EC20: 0 | ED20: 0 | EE20: 0 | EG20: 0 | EH20: 0 | EI20: 29String Beans | EJ20: 120 | EK20: 0 | EL20: 110 | EN20: 100 | EO20: 0 | EP20: 29Tomato | EQ20: 60 | ER20: 0 | ES20: 55 | EU20: 40 | EV20: 0 | EW20: 29White Potato | EX20: 120 | EY20: 0 | EZ20: 110 | FB20: 115 | FC20: 0 | FE20: 29Onion, Red | FF20: 80 | FG20: 0 | FH20: 80 | FJ20: 80 | FK20: 0 | FL20: 29Garlic, Native | FM20: 390 | FN20: 0 | FO20: 400 | FQ20: 400 | FR20: 0 | FS20: 29Garlic, Imported | FT20: 0 | FU20: 0 | FV20: 0 | FX20: 0 | FY20: 0 | FZ20: 29Ginger, Hawaiian | GA20: 90 | GB20: 0 | GC20: 85 | GE20: 85 | GF20: 0 | GH20: 29Banana, Lakatan | GI20: 0 | GJ20: 0 | GK20: 0 | GM20: 0 | GN20: 0 | GO20: 29Banana, Latundan | GP20: 60 | GQ20: 0 | GR20: 85 | GT20: 80 | GU20: 0 | GV20: 29Calamansi | GW20: 90 | GX20: 0 | GY20: 80 | HA20: 75 | HB20: 0 | HC20: 29Mango, Carabao | HD20: 0 | HE20: 0 | HF20: 0 | HH20: 0 | HI20: 0 | HJ20: 29Papaya | HK20: 75 | HL20: 0 | HM20: 75 | HO20: 65 | HP20: 0 | HR20: 29Cooking oil | HS20: 0 | HT20: 0 | HU20: 0 | HW20: 0 | HX20: 0 | HY20: 29Brown Sugar | HZ20: 82.2 | IA20: 0 | IB20: 73.7 | ID20: 73.7 | IE20: 0 | IF20: 29Refined Sugar | IG20: 0 | IH20: 0 | II20: 0 | IK20: 0 | IL20: 0
A21: 33 | B21: La Union | C21: 33Rice, Special | D21: 61 | E21: 0 | F21: 61 | H21: 62.5 | I21: 0 | J21: 33Rice, Well Milled | K21: 54.5 | L21: 0 | M21: 53 | O21: 53 | P21: 0 | Q21: 33Rice, Regular Milled | R21: 51 | S21: 0 | T21: 51 | V21: 51 | W21: 0 | Y21: 33Fresh Beef, Meat with Bones | Z21: 350 | AA21: 0 | AB21: 350 | AD21: 355 | AE21: 0 | AF21: 33Fresh Beef, Pure Meat | AG21: 0 | AH21: 0 | AI21: 0 | AK21: 0 | AL21: 0 | AM21: 33Fresh Pork, Kasim | AN21: 310 | AO21: 0 | AP21: 315 | AR21: 315 | AS21: 0 | AT21: 33Fresh Pork, Liempo | AU21: 305 | AV21: 0 | AW21: 310 | AY21: 315 | AZ21: 0 | BA21: 33Fresh Pork, Meat with Bones | BB21: 295 | BC21: 0 | BD21: 300 | BF21: 300 | BG21: 0 | BH21: 33Dressed Chicken | BI21: 190 | BJ21: 0 | BK21: 185 | BM21: 195 | BN21: 0 | BO21: 33Chicken egg, med. (piece) | BP21: 8.5 | BQ21: 0 | BR21: 8 | BT21: 8 | BU21: 0 | BW21: 33Bangus | BX21: 170 | BY21: 0 | BZ21: 150 | CB21: 145 | CC21: 0 | CD21: 33Galunggong | CE21: 200 | CF21: 0 | CG21: 240 | CI21: 235 | CJ21: 0 | CK21: 33Tilapia | CL21: 110 | CM21: 0 | CN21: 110 | CP21: 105 | CQ21: 0 | CS21: 33Ampalaya | CT21: 0 | CU21: 0 | CV21: 0 | CX21: 0 | CY21: 0 | CZ21: 33Cabbage | DA21: 50 | DB21: 0 | DC21: 50 | DE21: 40 | DF21: 0 | DG21: 33Carrot | DH21: 120 | DI21: 0 | DJ21: 130 | DL21: 145 | DM21: 0 | DN21: 33Eggplant | DO21: 40 | DP21: 0 | DQ21: 40 | DS21: 42.5 | DT21: 0 | DU21: 33Baguio Beans | DV21: 110 | DW21: 0 | DX21: 80 | DZ21: 75 | EA21: 0 | EB21: 33Pechay, Native | EC21: 71.43 | ED21: 0 | EE21: 71.43 | EG21: 71.43 | EH21: 0 | EI21: 33String Beans | EJ21: 55 | EK21: 0 | EL21: 65 | EN21: 60 | EO21: 0 | EP21: 33Tomato | EQ21: 55 | ER21: 0 | ES21: 40 | EU21: 35 | EV21: 0 | EW21: 33White Potato | EX21: 120 | EY21: 0 | EZ21: 140 | FB21: 120 | FC21: 0 | FE21: 33Onion, Red | FF21: 0 | FG21: 0 | FH21: 0 | FJ21: 0 | FK21: 0 | FL21: 33Garlic, Native | FM21: 415 | FN21: 0 | FO21: 415 | FQ21: 350 | FR21: 0 | FS21: 33Garlic, Imported | FT21: 0 | FU21: 0 | FV21: 0 | FX21: 0 | FY21: 0 | FZ21: 33Ginger, Hawaiian | GA21: 90 | GB21: 0 | GC21: 80 | GE21: 80 | GF21: 0 | GH21: 33Banana, Lakatan | GI21: 120 | GJ21: 0 | GK21: 120 | GM21: 120 | GN21: 0 | GO21: 33Banana, Latundan | GP21: 0 | GQ21: 0 | GR21: 0 | GT21: 0 | GU21: 0 | GV21: 33Calamansi | GW21: 82.5 | GX21: 0 | GY21: 75 | HA21: 70 | HB21: 0 | HC21: 33Mango, Carabao | HD21: 160 | HE21: 0 | HF21: 145 | HH21: 157.5 | HI21: 0 | HJ21: 33Papaya | HK21: 60 | HL21: 0 | HM21: 60 | HO21: 60 | HP21: 0 | HR21: 33Cooking oil | HS21: 0 | HT21: 0 | HU21: 0 | HW21: 0 | HX21: 0 | HY21: 33Brown Sugar | HZ21: 83 | IA21: 0 | IB21: 83 | ID21: 83 | IE21: 0 | IF21: 33Refined Sugar | IG21: 0 | IH21: 0 | II21: 0 | IK21: 0 | IL21: 0
A22: 55 | B22: Pangasinan | C22: 55Rice, Special | D22: 61.5 | E22: 0 | F22: 62.5 | H22: 62.5 | I22: 0 | J22: 55Rice, Well Milled | K22: 55.5 | L22: 0 | M22: 54.5 | O22: 54.5 | P22: 0 | Q22: 55Rice, Regular Milled | R22: 48.5 | S22: 0 | T22: 48.5 | V22: 48.5 | W22: 0 | Y22: 55Fresh Beef, Meat with Bones | Z22: 367 | AA22: 0 | AB22: 372 | AD22: 372 | AE22: 0 | AF22: 55Fresh Beef, Pure Meat | AG22: 412.5 | AH22: 0 | AI22: 461 | AK22: 461 | AL22: 0 | AM22: 55Fresh Pork, Kasim | AN22: 342.5 | AO22: 0 | AP22: 357.5 | AR22: 357.5 | AS22: 0 | AT22: 55Fresh Pork, Liempo | AU22: 371 | AV22: 0 | AW22: 396 | AY22: 396 | AZ22: 0 | BA22: 55Fresh Pork, Meat with Bones | BB22: 320 | BC22: 0 | BD22: 330 | BF22: 330 | BG22: 0 | BH22: 55Dressed Chicken | BI22: 182.5 | BJ22: 0 | BK22: 187.5 | BM22: 187.5 | BN22: 0 | BO22: 55Chicken egg, med. (piece) | BP22: 8.5 | BQ22: 0 | BR22: 8.5 | BT22: 8.5 | BU22: 0 | BW22: 55Bangus | BX22: 205 | BY22: 0 | BZ22: 200 | CB22: 185 | CC22: 0 | CD22: 55Galunggong | CE22: 240 | CF22: 0 | CG22: 245 | CI22: 245 | CJ22: 0 | CK22: 55Tilapia | CL22: 142.5 | CM22: 0 | CN22: 142.5 | CP22: 145 | CQ22: 0 | CS22: 55Ampalaya | CT22: 60 | CU22: 0 | CV22: 75 | CX22: 65 | CY22: 0 | CZ22: 55Cabbage | DA22: 45 | DB22: 0 | DC22: 42.5 | DE22: 45 | DF22: 0 | DG22: 55Carrot | DH22: 92.5 | DI22: 0 | DJ22: 122.5 | DL22: 90 | DM22: 0 | DN22: 55Eggplant | DO22: 89 | DP22: 0 | DQ22: 63.5 | DS22: 70.5 | DT22: 0 | DU22: 55Baguio Beans | DV22: 0 | DW22: 0 | DX22: 0 | DZ22: 0 | EA22: 0 | EB22: 55Pechay, Native | EC22: 45 | ED22: 0 | EE22: 42.5 | EG22: 40 | EH22: 0 | EI22: 55String Beans | EJ22: 95 | EK22: 0 | EL22: 85 | EN22: 55 | EO22: 0 | EP22: 55Tomato | EQ22: 80 | ER22: 0 | ES22: 39.5 | EU22: 35 | EV22: 0 | EW22: 55White Potato | EX22: 120 | EY22: 0 | EZ22: 132.5 | FB22: 120 | FC22: 0 | FE22: 55Onion, Red | FF22: 105 | FG22: 0 | FH22: 72.5 | FJ22: 75 | FK22: 0 | FL22: 55Garlic, Native | FM22: 140 | FN22: 0 | FO22: 150 | FQ22: 140 | FR22: 0 | FS22: 55Garlic, Imported | FT22: 0 | FU22: 0 | FV22: 0 | FX22: 0 | FY22: 0 | FZ22: 55Ginger, Hawaiian | GA22: 79 | GB22: 0 | GC22: 75.5 | GE22: 90 | GF22: 0 | GH22: 55Banana, Lakatan | GI22: 117.5 | GJ22: 0 | GK22: 112.5 | GM22: 110 | GN22: 0 | GO22: 55Banana, Latundan | GP22: 62.5 | GQ22: 0 | GR22: 60 | GT22: 55 | GU22: 0 | GV22: 55Calamansi | GW22: 75 | GX22: 0 | GY22: 62.5 | HA22: 65 | HB22: 0 | HC22: 55Mango, Carabao | HD22: 0 | HE22: 0 | HF22: 0 | HH22: 0 | HI22: 0 | HJ22: 55Papaya | HK22: 45 | HL22: 0 | HM22: 45 | HO22: 45 | HP22: 0 | HR22: 55Cooking oil | HS22: 112.68 | HT22: 0 | HU22: 112.68 | HW22: 112.68 | HX22: 0 | HY22: 55Brown Sugar | HZ22: 74 | IA22: 0 | IB22: 71.5 | ID22: 71.5 | IE22: 0 | IF22: 55Refined Sugar | IG22: 81 | IH22: 0 | II22: 78.5 | IK22: 78.5 | IL22: 0
A23: R2 | B23: II - Cagayan Valley | C23: R2Rice, Special | D23: 64.07 | E23: 0 | F23: 63.15 | H23: 62.86 | I23: 0 | J23: R2Rice, Well Milled | K23: 56.95 | L23: 0 | M23: 55.8 | O23: 55.57 | P23: 0 | Q23: R2Rice, Regular Milled | R23: 46.38 | S23: 0 | T23: 45.29 | V23: 46.13 | W23: 0 | Y23: R2Fresh Beef, Meat with Bones | Z23: 318.5 | AA23: 0 | AB23: 320.5 | AD23: 320.5 | AE23: 0 | AF23: R2Fresh Beef, Pure Meat | AG23: 363.75 | AH23: 0 | AI23: 367.5 | AK23: 342.5 | AL23: 0 | AM23: R2Fresh Pork, Kasim | AN23: 293.5 | AO23: 0 | AP23: 301.5 | AR23: 304.5 | AS23: 0 | AT23: R2Fresh Pork, Liempo | AU23: 303 | AV23: 0 | AW23: 310 | AY23: 313 | AZ23: 0 | BA23: R2Fresh Pork, Meat with Bones | BB23: 284 | BC23: 0 | BD23: 292 | BF23: 297 | BG23: 0 | BH23: R2Dressed Chicken | BI23: 195 | BJ23: 0 | BK23: 191 | BM23: 192 | BN23: 0 | BO23: R2Chicken egg, med. (piece) | BP23: 9.13 | BQ23: 0 | BR23: 8.95 | BT23: 8.83 | BU23: 0 | BW23: R2Bangus | BX23: 217.5 | BY23: 0 | BZ23: 218 | CB23: 217.5 | CC23: 0 | CD23: R2Galunggong | CE23: 210 | CF23: 0 | CG23: 211 | CI23: 204 | CJ23: 0 | CK23: R2Tilapia | CL23: 151.88 | CM23: 0 | CN23: 151.88 | CP23: 150.63 | CQ23: 0 | CS23: R2Ampalaya | CT23: 108.13 | CU23: 0 | CV23: 116.25 | CX23: 120 | CY23: 0 | CZ23: R2Cabbage | DA23: 47.5 | DB23: 0 | DC23: 44.8 | DE23: 44.5 | DF23: 0 | DG23: R2Carrot | DH23: 83.75 | DI23: 0 | DJ23: 100 | DL23: 100.01 | DM23: 0 | DN23: R2Eggplant | DO23: 82.5 | DP23: 0 | DQ23: 81.5 | DS23: 77.5 | DT23: 0 | DU23: R2Baguio Beans | DV23: 67.5 | DW23: 0 | DX23: 70 | DZ23: 77.5 | EA23: 0 | EB23: R2Pechay, Native | EC23: 120 | ED23: 0 | EE23: 75 | EG23: 71.88 | EH23: 0 | EI23: R2String Beans | EJ23: 114.38 | EK23: 0 | EL23: 101.25 | EN23: 106.25 | EO23: 0 | EP23: R2Tomato | EQ23: 96.25 | ER23: 0 | ES23: 80.63 | EU23: 52.5 | EV23: 0 | EW23: R2White Potato | EX23: 131 | EY23: 0 | EZ23: 137 | FB23: 132.5 | FC23: 0 | FE23: R2Onion, Red | FF23: 136 | FG23: 0 | FH23: 127 | FJ23: 126 | FK23: 0 | FL23: R2Garlic, Native | FM23: 120 | FN23: 0 | FO23: 150 | FQ23: 145 | FR23: 0 | FS23: R2Garlic, Imported | FT23: 141.67 | FU23: 0 | FV23: 156.67 | FX23: 156.67 | FY23: 0 | FZ23: R2Ginger, Hawaiian | GA23: 115 | GB23: 0 | GC23: 114 | GE23: 109 | GF23: 0 | GH23: R2Banana, Lakatan | GI23: 66.25 | GJ23: 0 | GK23: 64.38 | GM23: 65 | GN23: 0 | GO23: R2Banana, Latundan | GP23: 45 | GQ23: 0 | GR23: 45 | GT23: 46.25 | GU23: 0 | GV23: R2Calamansi | GW23: 119.38 | GX23: 0 | GY23: 116.88 | HA23: 115.63 | HB23: 0 | HC23: R2Mango, Carabao | HD23: 173.33 | HE23: 0 | HF23: 178.33 | HH23: 171.67 | HI23: 0 | HJ23: R2Papaya | HK23: 40 | HL23: 0 | HM23: 40.83 | HO23: 40.83 | HP23: 0 | HR23: R2Cooking oil | HS23: 108.94 | HT23: 0 | HU23: 108.94 | HW23: 108.94 | HX23: 0 | HY23: R2Brown Sugar | HZ23: 78.66 | IA23: 0 | IB23: 77.66 | ID23: 77.76 | IE23: 0 | IF23: R2Refined Sugar | IG23: 89 | IH23: 0 | II23: 88.75 | IK23: 87.75 | IL23: 0
A24: 9 | B24: Batanes | C24: 9Rice, Special | D24: 83 | E24: 0 | F24: 83 | H24: 83 | I24: 0 | J24: 9Rice, Well Milled | K24: 72 | L24: 0 | M24: 72 | O24: 72 | P24: 0 | Q24: 9Rice, Regular Milled | R24: 0 | S24: 0 | T24: 0 | V24: 0 | W24: 0 | Y24: 9Fresh Beef, Meat with Bones | Z24: 250 | AA24: 0 | AB24: 250 | AD24: 250 | AE24: 0 | AF24: 9Fresh Beef, Pure Meat | AG24: 0 | AH24: 0 | AI24: 0 | AK24: 0 | AL24: 0 | AM24: 9Fresh Pork, Kasim | AN24: 280 | AO24: 0 | AP24: 280 | AR24: 290 | AS24: 0 | AT24: 9Fresh Pork, Liempo | AU24: 280 | AV24: 0 | AW24: 280 | AY24: 290 | AZ24: 0 | BA24: 9Fresh Pork, Meat with Bones | BB24: 280 | BC24: 0 | BD24: 280 | BF24: 290 | BG24: 0 | BH24: 9Dressed Chicken | BI24: 230 | BJ24: 0 | BK24: 230 | BM24: 235 | BN24: 0 | BO24: 9Chicken egg, med. (piece) | BP24: 11.5 | BQ24: 0 | BR24: 11.5 | BT24: 11.5 | BU24: 0 | BW24: 9Bangus | BX24: 275 | BY24: 0 | BZ24: 275 | CB24: 270 | CC24: 0 | CD24: 9Galunggong | CE24: 200 | CF24: 0 | CG24: 200 | CI24: 200 | CJ24: 0 | CK24: 9Tilapia | CL24: 0 | CM24: 0 | CN24: 0 | CP24: 0 | CQ24: 0 | CS24: 9Ampalaya | CT24: 200 | CU24: 0 | CV24: 215 | CX24: 210 | CY24: 0 | CZ24: 9Cabbage | DA24: 75 | DB24: 0 | DC24: 60 | DE24: 45 | DF24: 0 | DG24: 9Carrot | DH24: 0 | DI24: 0 | DJ24: 0 | DL24: 0 | DM24: 0 | DN24: 9Eggplant | DO24: 180 | DP24: 0 | DQ24: 190 | DS24: 165 | DT24: 0 | DU24: 9Baguio Beans | DV24: 0 | DW24: 0 | DX24: 0 | DZ24: 0 | EA24: 0 | EB24: 9Pechay, Native | EC24: 70 | ED24: 0 | EE24: 70 | EG24: 70 | EH24: 0 | EI24: 9String Beans | EJ24: 175 | EK24: 0 | EL24: 185 | EN24: 175 | EO24: 0 | EP24: 9Tomato | EQ24: 150 | ER24: 0 | ES24: 125 | EU24: 90 | EV24: 0 | EW24: 9White Potato | EX24: 225 | EY24: 0 | EZ24: 225 | FB24: 215 | FC24: 0 | FE24: 9Onion, Red | FF24: 225 | FG24: 0 | FH24: 240 | FJ24: 225 | FK24: 0 | FL24: 9Garlic, Native | FM24: 0 | FN24: 0 | FO24: 0 | FQ24: 0 | FR24: 0 | FS24: 9Garlic, Imported | FT24: 0 | FU24: 0 | FV24: 0 | FX24: 0 | FY24: 0 | FZ24: 9Ginger, Hawaiian | GA24: 215 | GB24: 0 | GC24: 215 | GE24: 215 | GF24: 0 | GH24: 9Banana, Lakatan | GI24: 0 | GJ24: 0 | GK24: 0 | GM24: 0 | GN24: 0 | GO24: 9Banana, Latundan | GP24: 60 | GQ24: 0 | GR24: 60 | GT24: 60 | GU24: 0 | GV24: 9Calamansi | GW24: 210 | GX24: 0 | GY24: 200 | HA24: 200 | HB24: 0 | HC24: 9Mango, Carabao | HD24: 245 | HE24: 0 | HF24: 265 | HH24: 245 | HI24: 0 | HJ24: 9Papaya | HK24: 0 | HL24: 0 | HM24: 0 | HO24: 0 | HP24: 0 | HR24: 9Cooking oil | HS24: 0 | HT24: 0 | HU24: 0 | HW24: 0 | HX24: 0 | HY24: 9Brown Sugar | HZ24: 97.5 | IA24: 0 | IB24: 97.5 | ID24: 97.5 | IE24: 0 | IF24: 9Refined Sugar | IG24: 100 | IH24: 0 | II24: 100 | IK24: 100 | IL24: 0
A25: 15 | B25: Cagayan | C25: 15Rice, Special | D25: 61.63 | E25: 0 | F25: 59.69 | H25: 59.69 | I25: 0 | J25: 15Rice, Well Milled | K25: 54.92 | L25: 0 | M25: 51.89 | O25: 51.89 | P25: 0 | Q25: 15Rice, Regular Milled | R25: 44.5 | S25: 0 | T25: 41.53 | V25: 41.53 | W25: 0 | Y25: 15Fresh Beef, Meat with Bones | Z25: 300 | AA25: 0 | AB25: 310 | AD25: 300 | AE25: 0 | AF25: 15Fresh Beef, Pure Meat | AG25: 347.5 | AH25: 0 | AI25: 355 | AK25: 305 | AL25: 0 | AM25: 15Fresh Pork, Kasim | AN25: 270 | AO25: 0 | AP25: 270 | AR25: 270 | AS25: 0 | AT25: 15Fresh Pork, Liempo | AU25: 285 | AV25: 0 | AW25: 285 | AY25: 285 | AZ25: 0 | BA25: 15Fresh Pork, Meat with Bones | BB25: 260 | BC25: 0 | BD25: 260 | BF25: 275 | BG25: 0 | BH25: 15Dressed Chicken | BI25: 155 | BJ25: 0 | BK25: 155 | BM25: 155 | BN25: 0 | BO25: 15Chicken egg, med. (piece) | BP25: 9 | BQ25: 0 | BR25: 9 | BT25: 8.75 | BU25: 0 | BW25: 15Bangus | BX25: 180 | BY25: 0 | BZ25: 180 | CB25: 180 | CC25: 0 | CD25: 15Galunggong | CE25: 190 | CF25: 0 | CG25: 195 | CI25: 190 | CJ25: 0 | CK25: 15Tilapia | CL25: 135 | CM25: 0 | CN25: 135 | CP25: 135 | CQ25: 0 | CS25: 15Ampalaya | CT25: 42.5 | CU25: 0 | CV25: 60 | CX25: 75 | CY25: 0 | CZ25: 15Cabbage | DA25: 22.5 | DB25: 0 | DC25: 24 | DE25: 30 | DF25: 0 | DG25: 15Carrot | DH25: 57.5 | DI25: 0 | DJ25: 87.5 | DL25: 85 | DM25: 0 | DN25: 15Eggplant | DO25: 27.5 | DP25: 0 | DQ25: 32.5 | DS25: 47.5 | DT25: 0 | DU25: 15Baguio Beans | DV25: 0 | DW25: 0 | DX25: 0 | DZ25: 0 | EA25: 0 | EB25: 15Pechay, Native | EC25: 0 | ED25: 0 | EE25: 0 | EG25: 0 | EH25: 0 | EI25: 15String Beans | EJ25: 125 | EK25: 0 | EL25: 57.5 | EN25: 72.5 | EO25: 0 | EP25: 15Tomato | EQ25: 52.5 | ER25: 0 | ES25: 30 | EU25: 32.5 | EV25: 0 | EW25: 15White Potato | EX25: 90 | EY25: 0 | EZ25: 90 | FB25: 87.5 | FC25: 0 | FE25: 15Onion, Red | FF25: 105 | FG25: 0 | FH25: 65 | FJ25: 75 | FK25: 0 | FL25: 15Garlic, Native | FM25: 70 | FN25: 0 | FO25: 130 | FQ25: 120 | FR25: 0 | FS25: 15Garlic, Imported | FT25: 0 | FU25: 0 | FV25: 0 | FX25: 0 | FY25: 0 | FZ25: 15Ginger, Hawaiian | GA25: 65 | GB25: 0 | GC25: 65 | GE25: 65 | GF25: 0 | GH25: 15Banana, Lakatan | GI25: 57.5 | GJ25: 0 | GK25: 57.5 | GM25: 50 | GN25: 0 | GO25: 15Banana, Latundan | GP25: 30 | GQ25: 0 | GR25: 30 | GT25: 32.5 | GU25: 0 | GV25: 15Calamansi | GW25: 0 | GX25: 0 | GY25: 0 | HA25: 0 | HB25: 0 | HC25: 15Mango, Carabao | HD25: 0 | HE25: 0 | HF25: 0 | HH25: 0 | HI25: 0 | HJ25: 15Papaya | HK25: 0 | HL25: 0 | HM25: 0 | HO25: 0 | HP25: 0 | HR25: 15Cooking oil | HS25: 105.37 | HT25: 0 | HU25: 105.37 | HW25: 105.37 | HX25: 0 | HY25: 15Brown Sugar | HZ25: 83.8 | IA25: 0 | IB25: 83.8 | ID25: 83.8 | IE25: 0 | IF25: 15Refined Sugar | IG25: 96.5 | IH25: 0 | II25: 96.5 | IK25: 96.5 | IL25: 0
